Workbook
Name List_FS_IT감사RA: DB_cList!$J$118
Name List_FS_KICS: DB_cList!$J$116:$J$117
Name List_FS_계획단계: DB_cList!$J$4:$J$5
Name List_FS_내부통제: DB_cList!$J$76:$J$115
Name List_FS_대분류: DB_cList!$G$3:$G$13
Name List_FS_부채및자본: DB_cList!$J$36:$J$52
Name List_FS_분반기검토: DB_cList!$J$3
Name List_FS_수익비용: DB_cList!$J$53:$J$64
Name List_FS_연결: DB_cList!$J$72:$J$75
Name List_FS_자산: DB_cList!$J$9:$J$35
Name List_FS_재무제표수준위험: DB_cList!$J$6:$J$8
Name List_FS_종결단계: DB_cList!$J$65:$J$71
Name List_IT감사RA: DB_cList!$E$87
Name List_Members: Tbl_Members[이름]
Name List_계획단계: DB_cList!$E$4:$E$5
Name List_내부통제: DB_cList!$E$63:$E$86
Name List_대분류: DB_cList!$B$3:$B$12
Name List_부채및자본: DB_cList!$E$29:$E$42
Name List_분반기검토: DB_cList!$E$3
Name List_수익비용: DB_cList!$E$43:$E$53
Name List_업무개시연월: DB_cList!$L$3:$L$19
Name List_연결: DB_cList!$E$59:$E$62
Name List_자산: DB_cList!$E$9:$E$28
Name List_재무제표수준위험: DB_cList!$E$6:$E$8
Name List_종결단계: DB_cList!$E$54:$E$58
Name Range_Header_1to12: 'D_2606 budget template'!$K$21:$V$21
Name Range_Members: 'C_ET 구성원 정보'!$B$7:$I$30
Name Range_TblBudgetAll: 'D_2606 budget template'!$B$21:$X$114
Name Range_Template상단: 'D_2606 budget template'!$B$3:$C$19
Name Range_기본정보1: 'B_ET 기본정보'!$B$4:$D$15
Name Range_기본정보2: 'B_ET 기본정보'!$B$19:$E$24
Name Range_기본정보3: 'B_ET 기본정보'!$B$28:$D$33

Sheet A_작성 Instruction
A1: A 작성 Instruction

Sheet B_ET 기본정보
B2: 1. 당기 감사 Client 기본 정보
B4: 구분 | C4: 선택항목 | D4: 선택목록
B5: 1) 표준산업분류 | C5: ⑤ 도소매업 | D5: ① 제조업,② 서비스업,③ 건설업,④ 금융업,⑤ 도소매업,⑥ 기타
B6: 2) 자산규모 | C6: ⑤ 별도 1천억미만 ~ 500억이상 | D6: ① 별도 2조&연결 5조(자산매출평균) 이상,② 별도 2조이상,③ 별도 2조미만 ~ 5천억이상,④ 별도 5천억미만 ~ 1천억이상,⑤ 별도 1천억미만 ~ 500억이상,⑥ 별도 500억미만 ~ 200억이상,⑦ 별도 200억 미만
B7: 3) 상장/비상장 | C7: ⑥ 비상장 | D7: ① 유가증권상장,② 코스닥상장,③ 코넥스상장,④ 채권상장,⑤ 상장예정,⑥ 비상장
B8: 4) 사업보고서 제출 | C8: ② 사업보고서 제출미대상 | D8: ① 사업보고서 제출대상,② 사업보고서 제출미대상
B9: 5) GAAP | C9: ① IFRS | D9: ① IFRS,② 일반기준
B10: 6) 연결재무제표작성 | C10: ② 미작성 | D10: ① 작성,② 미작성
B11: 7) 연결자회사수 | C11: ① 없음 | D11: ① 없음,② 10개 이하,③ 11개~50개,④ 51개~100개,⑤ 100개 초과
B12: 8) 내부회계관리제도 | C12: ② 내부회계감사(별도) | D12: ① 내부회계감사(연결),② 내부회계감사(별도),③ 내부회계검토,④ 의무없음
B13: 9) 초도감사 | C13: ① 초도감사 | D13: ① 초도감사,② 계속감사
B14: 10) 업무개시일 | C14: 45748 | D14: 업무개시 연월을 기재 (25년 1월 ~ 26년 5월 중 선택)
B15: 11) 총계약시간 | C15: 500
B17: 2. 프로젝트 코드 기본정보
B19: 구분 | C19: 비고 | D19: 사번 | E19: 표감 activity mapping
B20: 1) Project code | C20: 15916-01-012
B21: 2) Project 명 | C21: (주)에뛰드/2025년 회계감사
B22: 3) 본부명 | C22: CM Audit 1
B23: 4) EL | C23: 최성우 | D23: 170661 | E23: 재무제표기말감사
B24: 5) PM | C24: 이창욱 | D24: 280570 | E24: 재무제표기말감사
B26: 3. 프로젝트 코드 QRP,RM, EL, PM 시간 정보
B28: 구분 | C28: 시간 | D28: 표감 activity mapping
B29: 1) QRP | C29: 0 | D29: QRP
B30: 2) RM/CRS/M&T 등 | C30: 0 | D30: QC-(RM, ACS, M&T 등)
B31: 3) FLDT-EL | C31: 20 | D31: 기타
B32: 4) FLDT-PM | C32: 55 | D32: 기타
B33: 5) RA-EL,PM | C33: 0 | D33: SPA_내부통제

Sheet C_ET 구성원 정보
B2: 1. 감사 ET 구성원 정보 입력
B3: 1) 동 sheet에 이름과 사번 입력 시 budget template에서 "이름"기준 입력을 지원합니다.
B4: 2) 동명이인인 경우, 이름을 상이하게 조정하여 기재부탁드립니다.(e.g. 김삼일32, 김삼일26)
B5: 3) FLDT/RA EL과 PM은 기재할 필요가 없습니다. | G5: Optional
G6: =SUM(Tbl_Members[사전 배부]) -> 335 | H6: =SUM(Tbl_Members[Template 반영현황]) -> 348
B7: 구분 | C7: 이름 | D7: 사번 | E7: 표감 activity mapping | F7: 비고 | G7: 사전 배부 | H7: Template 반영현황 | I7: 예산대비 반영차이
B8: FLDT 구성원 | C8: 서보경 | D8: 260666 | E8: 재무제표기말감사 | F8: ET 구성원 정보 입력 | G8: 1 | H8: =SUMIF(Tbl_Budget[사번],D8,Tbl_Budget[Budget 합계]) -> 1 | I8: =G8-H8 -> 0
B9: FLDT 구성원 | C9: 이채연 | D9: 310625 | E9: 재무제표기말감사 | F9: ET 구성원 정보 입력 | G9: 120 | H9: =SUMIF(Tbl_Budget[사번],D9,Tbl_Budget[Budget 합계]) -> 127 | I9: =G9-H9 -> -7
B10: FLDT 구성원 | C10: 최우금 | D10: 330590 | E10: 재무제표기말감사 | F10: ET 구성원 정보 입력 | G10: 105 | H10: =SUMIF(Tbl_Budget[사번],D10,Tbl_Budget[Budget 합계]) -> 108 | I10: =G10-H10 -> -3
B11: FLDT 구성원 | C11: 정다희 | D11: 340644 | E11: 재무제표기말감사 | F11: ET 구성원 정보 입력 | G11: 105 | H11: =SUMIF(Tbl_Budget[사번],D11,Tbl_Budget[Budget 합계]) -> 108 | I11: =G11-H11 -> -3
B12: FLDT 구성원 | C12: TBD_Associate_1 | D12: TBD_Associate_1 | E12: 재무제표기말감사 | F12: ET 구성원 정보 입력 | G12: 0 | H12: =SUMIF(Tbl_Budget[사번],D12,Tbl_Budget[Budget 합계]) -> 0 | I12: =G12-H12 -> 0
B13: FLDT 구성원 | F13: ET 구성원 정보 입력 | H13: =SUMIF(Tbl_Budget[사번],D13,Tbl_Budget[Budget 합계]) -> 0 | I13: =G13-H13 -> 0
B14: FLDT 구성원 | F14: ET 구성원 정보 입력 | H14: =SUMIF(Tbl_Budget[사번],D14,Tbl_Budget[Budget 합계]) -> 0 | I14: =G14-H14 -> 0
B15: FLDT 구성원 | F15: Defalut로 설정(인원이 특정되지 않는 경우 숫자 및 직급을 추가하여 인원 구분, 불필요시 행삭제) | H15: =SUMIF(Tbl_Budget[사번],D15,Tbl_Budget[Budget 합계]) -> 0 | I15: =G15-H15 -> 0
B16: FLDT 구성원 | F16: Defalut로 설정(인원이 특정되지 않는 경우 숫자 및 직급을 추가하여 인원 구분, 불필요시 행삭제) | H16: =SUMIF(Tbl_Budget[사번],D16,Tbl_Budget[Budget 합계]) -> 0 | I16: =G16-H16 -> 0
B17: FLDT 구성원 | F17: Defalut로 설정(인원이 특정되지 않는 경우 숫자 및 직급을 추가하여 인원 구분, 불필요시 행삭제) | H17: =SUMIF(Tbl_Budget[사번],D17,Tbl_Budget[Budget 합계]) -> 0 | I17: =G17-H17 -> 0
B18: FLDT 구성원 | C18: New comer1 | D18: New comer1 | E18: New Staff | F18: Defalut로 설정(인원이 특정되지 않는 경우 숫자를 추가하여 인원 구분, 불필요시 행삭제) | H18: =SUMIF(Tbl_Budget[사번],D18,Tbl_Budget[Budget 합계]) -> 0 | I18: =G18-H18 -> 0
B19: FLDT 구성원 | F19: Defalut로 설정(인원이 특정되지 않는 경우 숫자를 추가하여 인원 구분, 불필요시 행삭제) | H19: =SUMIF(Tbl_Budget[사번],D19,Tbl_Budget[Budget 합계]) -> 0 | I19: =G19-H19 -> 0
B20: FLDT 구성원 | F20: Defalut로 설정(인원이 특정되지 않는 경우 숫자를 추가하여 인원 구분, 불필요시 행삭제) | H20: =SUMIF(Tbl_Budget[사번],D20,Tbl_Budget[Budget 합계]) -> 0 | I20: =G20-H20 -> 0
B21: FLDT 구성원 | F21: Defalut로 설정(인원이 특정되지 않는 경우 숫자를 추가하여 인원 구분, 불필요시 행삭제) | H21: =SUMIF(Tbl_Budget[사번],D21,Tbl_Budget[Budget 합계]) -> 0 | I21: =G21-H21 -> 0
B22: FLDT 구성원 | F22: Defalut로 설정(인원이 특정되지 않는 경우 숫자를 추가하여 인원 구분, 불필요시 행삭제) | H22: =SUMIF(Tbl_Budget[사번],D22,Tbl_Budget[Budget 합계]) -> 0 | I22: =G22-H22 -> 0
B23: FLDT 구성원 | F23: Defalut로 설정(인원이 특정되지 않는 경우 숫자를 추가하여 인원 구분, 불필요시 행삭제) | H23: =SUMIF(Tbl_Budget[사번],D23,Tbl_Budget[Budget 합계]) -> 0 | I23: =G23-H23 -> 0
B24: FLDT 구성원 | F24: Defalut로 설정(인원이 특정되지 않는 경우 숫자를 추가하여 인원 구분, 불필요시 행삭제) | H24: =SUMIF(Tbl_Budget[사번],D24,Tbl_Budget[Budget 합계]) -> 0 | I24: =G24-H24 -> 0
B25: FLDT 구성원 | F25: Defalut로 설정(인원이 특정되지 않는 경우 숫자를 추가하여 인원 구분, 불필요시 행삭제) | H25: =SUMIF(Tbl_Budget[사번],D25,Tbl_Budget[Budget 합계]) -> 0 | I25: =G25-H25 -> 0
B26: FLDT 구성원 | F26: Defalut로 설정(인원이 특정되지 않는 경우 숫자를 추가하여 인원 구분, 불필요시 행삭제) | H26: =SUMIF(Tbl_Budget[사번],D26,Tbl_Budget[Budget 합계]) -> 0 | I26: =G26-H26 -> 0
B27: FLDT 구성원 | F27: Defalut로 설정(인원이 특정되지 않는 경우 숫자를 추가하여 인원 구분, 불필요시 행삭제) | H27: =SUMIF(Tbl_Budget[사번],D27,Tbl_Budget[Budget 합계]) -> 0 | I27: =G27-H27 -> 0
B28: 지원 ET 구성원 | C28: Fulcrum | D28: Fulcrum | E28: Fulcrum | F28: Defalut로 설정(인원구분 없이 단일 항목으로만 사용) | H28: =SUMIF(Tbl_Budget[사번],D28,Tbl_Budget[Budget 합계]) -> 0 | I28: =G28-H28 -> 0
B29: 지원 ET 구성원 | C29: RA | D29: RA | E29: SPA_내부통제 | F29: Defalut로 설정(인원구분 없이 단일 항목으로만 사용) | H29: =SUMIF(Tbl_Budget[사번],D29,Tbl_Budget[Budget 합계]) -> 0 | I29: =G29-H29 -> 0
B30: 지원 ET 구성원 | C30: Specialist | D30: Specialist | E30: 기타 | F30: Defalut로 설정(인원구분 없이 단일 항목으로만 사용) | G30: 4 | H30: =SUMIF(Tbl_Budget[사번],D30,Tbl_Budget[Budget 합계]) -> 4 | I30: =G30-H30 -> 0
B31: ↑D시트 Budget Table 내의 구성원 | G31: ='B_ET 기본정보'!C31+'B_ET 기본정보'!C32 -> 75
B32: ↓D시트 Budget Table 밖의 구성원 | G32: =G31+G6 -> 410
B33: 구분 | C33: 이름 | D33: 사번 | E33: 표감 activity mapping | F33: 비고
B34: 지원 ET 구성원 | C34: QRP | D34: QRP | E34: QRP | F34: Defalut로 설정(인원구분 없이 단일 항목으로만 사용)
B35: 지원 ET 구성원 | C35: RM/CRS/M&T 등 | D35: RM/CRS/M&T 등 | E35: QC-(RM, ACS, M&T 등) | F35: Defalut로 설정(인원구분 없이 단일 항목으로만 사용)
B36: 지원 ET 구성원 | C36: FLDT-EL | D36: FLDT-EL | E36: 재무제표기말감사 | F36: Defalut로 설정(인원구분 없이 단일 항목으로만 사용)
B37: 지원 ET 구성원 | C37: FLDT-PM | D37: FLDT-PM | E37: 재무제표기말감사 | F37: Defalut로 설정(인원구분 없이 단일 항목으로만 사용)
B38: 지원 ET 구성원 | C38: RA-EL,PM | D38: RA-EL,PM | E38: SPA_내부통제 | F38: Defalut로 설정(인원구분 없이 단일 항목으로만 사용)

Sheet D_2606 budget template
B2: [Budget 기초정보 및 검증]
B3: 1) 계약시간 | C3: ='B_ET 기본정보'!C15 -> 500 | E3: < B_ET 기본정보 정보 자동입력
B4: 2) AX/DX Transition | C4: 77 | E4: < ET의 감사환경을 고려하여 Digital tool을 포함한 AX/DX Transition 적용 목표치를 입력 | H4: =C4/C3 -> 0.154
B5: 3) QRP, RM 등 시간 | C5: ='B_ET 기본정보'!C29+'B_ET 기본정보'!C30 -> 0 | E5: < B_ET 기본정보 정보 자동입력
B6: 4) FLDT-EL 시간 | C6: ='B_ET 기본정보'!C31 -> 20 | E6: < B_ET 기본정보 정보 자동입력
B7: 5) FLDT-PM 시간 | C7: ='B_ET 기본정보'!C32 -> 55 | E7: < B_ET 기본정보 정보 자동입력
B8: 6) RA-EL/PM 시간 | C8: ='B_ET 기본정보'!C33 -> 0 | E8: < B_ET 기본정보 정보 자동입력
B9: 7) ET controllable budget | C9: =C3-SUM(C4:C8) -> 348 | E9: < AX/DX Transition, EL/PM 투입 시간 고려 자동 산출
B10: 8-1) Fulcrum 활용 시간 | C10: =SUMIFS(Tbl_Budget[Budget 합계],Tbl_Budget[사번],"Fulcrum",Tbl_Budget[해당],"True") -> 0 | E10: < ET controllalble budget에 포함되어 있으며, Budget 입력 시 자동입력
B11: 8-2) RA-Staff 활용 시간 | C11: =SUMIFS(Tbl_Budget[Budget 합계],Tbl_Budget[사번],"RA",Tbl_Budget[해당],"True") -> 0 | E11: < ET controllalble budget에 포함되어 있으며, Budget 입력 시 자동입력
B12: 8-3) Specialist 활용 시간 | C12: =SUMIFS(Tbl_Budget[Budget 합계],Tbl_Budget[사번],"Specialist",Tbl_Budget[해당],"True") -> 4 | E12: < ET controllalble budget에 포함되어 있으며, Budget 입력 시 자동입력
B13: 8-4) FLDT budget | C13: =SUM(C9,-C10,-C11,-C12) -> 344 | E13: < FLDT에 배부되는 시간으로서 자동 산출
B14: 8-5) 지방/해외 출장 시간 | C14: 0 | E14: < 지방/해외 출장 시 소요되는 시간을 기재
B15: ① 배부 검증 - 전체 시간 | C15: =(C9-C14)-J20 -> 0 | E15: < D열 Scope여부 체크항목의 관리단위별 Budget 합계와 일치 필요
B16: ② 배부 검증 - FLDT 시간 | C16: =C13-C14-J19 -> 0 | E16: < D열 Scope여부 체크항목 중 FLDT 관리단위별 Budget 합계와 일치 필요
B17: ③ 배부 검증 - 월별합계검증 | C17: =SUM(Tbl_Budget[합계검증]) -> 0 | E17: < D열 Scope여부 체크항목 중 Budget 합계와 K열~V열 합계 일치 필요
B18: 9) Budget 작성 주기 | C18: =IF(OR(('B_ET 기본정보'!C7="⑥ 비상장"),('B_ET 기본정보'!C7="⑤ 상장예정")),"분기별","월별") -> 분기별
B19: 10) Template 작성 완료여부 | C19: =IF(AND(C9>0,C15=0,C16=0,C17=0),"작성완료",IF(C9<=0,"작업전","진행중")) -> 작성완료 | I19: FLDT외 | J19: =SUMIF(Tbl_Budget[해당], TRUE, Tbl_Budget[Budget 합계]) - (SUMIFS(Tbl_Budget[Budget 합계], Tbl_Budget[해당], TRUE, Tbl_Budget[Assignment], "RA") + SUMIFS(Tbl_Budget[Budget 합계], Tbl_Budget[해당], TRUE, Tbl_Budget[Assignment], "Specialist") + SUMIFS(Tbl_Budget[Budget 합계], Tbl_Budget[해당], TRUE, Tbl_Budget[Assignment], "Fulcrum")) -> 344 | K19: =SUMIF(Tbl_Budget[해당], TRUE, Tbl_Budget[1]) - (SUMIFS(Tbl_Budget[1], Tbl_Budget[해당], TRUE, Tbl_Budget[Assignment], "RA") + SUMIFS(Tbl_Budget[1], Tbl_Budget[해당], TRUE, Tbl_Budget[Assignment], "Specialist") + SUMIFS(Tbl_Budget[1], Tbl_Budget[해당], TRUE, Tbl_Budget[Assignment], "Fulcrum")) -> 0 | L19: =SUMIF(Tbl_Budget[해당], TRUE, Tbl_Budget[2]) - (SUMIFS(Tbl_Budget[2], Tbl_Budget[해당], TRUE, Tbl_Budget[Assignment], "RA") + SUMIFS(Tbl_Budget[2], Tbl_Budget[해당], TRUE, Tbl_Budget[Assignment], "Specialist") + SUMIFS(Tbl_Budget[2], Tbl_Budget[해당], TRUE, Tbl_Budget[Assignment], "Fulcrum")) -> 0 | M19: =SUMIF(Tbl_Budget[해당], TRUE, Tbl_Budget[3]) - (SUMIFS(Tbl_Budget[3], Tbl_Budget[해당], TRUE, Tbl_Budget[Assignment], "RA") + SUMIFS(Tbl_Budget[3], Tbl_Budget[해당], TRUE, Tbl_Budget[Assignment], "Specialist") + SUMIFS(Tbl_Budget[3], Tbl_Budget[해당], TRUE, Tbl_Budget[Assignment], "Fulcrum")) -> 53 | N19: =SUMIF(Tbl_Budget[해당], TRUE, Tbl_Budget[4]) - (SUMIFS(Tbl_Budget[4], Tbl_Budget[해당], TRUE, Tbl_Budget[Assignment], "RA") + SUMIFS(Tbl_Budget[4], Tbl_Budget[해당], TRUE, Tbl_Budget[Assignment], "Specialist") + SUMIFS(Tbl_Budget[4], Tbl_Budget[해당], TRUE, Tbl_Budget[Assignment], "Fulcrum")) -> 0 | O19: =SUMIF(Tbl_Budget[해당], TRUE, Tbl_Budget[5]) - (SUMIFS(Tbl_Budget[5], Tbl_Budget[해당], TRUE, Tbl_Budget[Assignment], "RA") + SUMIFS(Tbl_Budget[5], Tbl_Budget[해당], TRUE, Tbl_Budget[Assignment], "Specialist") + SUMIFS(Tbl_Budget[5], Tbl_Budget[해당], TRUE, Tbl_Budget[Assignment], "Fulcrum")) -> 0 | P19: =SUMIF(Tbl_Budget[해당], TRUE, Tbl_Budget[6]) - (SUMIFS(Tbl_Budget[6], Tbl_Budget[해당], TRUE, Tbl_Budget[Assignment], "RA") + SUMIFS(Tbl_Budget[6], Tbl_Budget[해당], TRUE, Tbl_Budget[Assignment], "Specialist") + SUMIFS(Tbl_Budget[6], Tbl_Budget[해당], TRUE, Tbl_Budget[Assignment], "Fulcrum")) -> 34 | Q19: =SUMIF(Tbl_Budget[해당], TRUE, Tbl_Budget[7]) - (SUMIFS(Tbl_Budget[7], Tbl_Budget[해당], TRUE, Tbl_Budget[Assignment], "RA") + SUMIFS(Tbl_Budget[7], Tbl_Budget[해당], TRUE, Tbl_Budget[Assignment], "Specialist") + SUMIFS(Tbl_Budget[7], Tbl_Budget[해당], TRUE, Tbl_Budget[Assignment], "Fulcrum")) -> 0 | R19: =SUMIF(Tbl_Budget[해당], TRUE, Tbl_Budget[8]) - (SUMIFS(Tbl_Budget[8], Tbl_Budget[해당], TRUE, Tbl_Budget[Assignment], "RA") + SUMIFS(Tbl_Budget[8], Tbl_Budget[해당], TRUE, Tbl_Budget[Assignment], "Specialist") + SUMIFS(Tbl_Budget[8], Tbl_Budget[해당], TRUE, Tbl_Budget[Assignment], "Fulcrum")) -> 0 | S19: =SUMIF(Tbl_Budget[해당], TRUE, Tbl_Budget[9]) - (SUMIFS(Tbl_Budget[9], Tbl_Budget[해당], TRUE, Tbl_Budget[Assignment], "RA") + SUMIFS(Tbl_Budget[9], Tbl_Budget[해당], TRUE, Tbl_Budget[Assignment], "Specialist") + SUMIFS(Tbl_Budget[9], Tbl_Budget[해당], TRUE, Tbl_Budget[Assignment], "Fulcrum")) -> 96 | T19: =SUMIF(Tbl_Budget[해당], TRUE, Tbl_Budget[10]) - (SUMIFS(Tbl_Budget[10], Tbl_Budget[해당], TRUE, Tbl_Budget[Assignment], "RA") + SUMIFS(Tbl_Budget[10], Tbl_Budget[해당], TRUE, Tbl_Budget[Assignment], "Specialist") + SUMIFS(Tbl_Budget[10], Tbl_Budget[해당], TRUE, Tbl_Budget[Assignment], "Fulcrum")) -> 141 | U19: =SUMIF(Tbl_Budget[해당], TRUE, Tbl_Budget[11]) - (SUMIFS(Tbl_Budget[11], Tbl_Budget[해당], TRUE, Tbl_Budget[Assignment], "RA") + SUMIFS(Tbl_Budget[11], Tbl_Budget[해당], TRUE, Tbl_Budget[Assignment], "Specialist") + SUMIFS(Tbl_Budget[11], Tbl_Budget[해당], TRUE, Tbl_Budget[Assignment], "Fulcrum")) -> 20 | V19: =SUMIF(Tbl_Budget[해당], TRUE, Tbl_Budget[12]) - (SUMIFS(Tbl_Budget[12], Tbl_Budget[해당], TRUE, Tbl_Budget[Assignment], "RA") + SUMIFS(Tbl_Budget[12], Tbl_Budget[해당], TRUE, Tbl_Budget[Assignment], "Specialist") + SUMIFS(Tbl_Budget[12], Tbl_Budget[해당], TRUE, Tbl_Budget[Assignment], "Fulcrum")) -> 0 | X19: =SUM(T19:V19)/C13 -> 0.46802326 | Y19: FLDT 기말비율
E20: =SUM(Tbl_Budget[25/06 Debriefing실적]) -> 0 | F20: {=_xlfn.XLOOKUP('B_ET 기본정보'!C5&'B_ET 기본정보'!C6&'B_ET 기본정보'!C7&'B_ET 기본정보'!C10&'B_ET 기본정보'!C12,DB_tMap!B:B&DB_tMap!C:C&DB_tMap!D:D&DB_tMap!E:E&DB_tMap!F:F,DB_tMap!G:G,"B시트 정보를 채워주세요")} -> C2 | G20: E/F/G열은 작성에 도움을 주기 위한 단순참고용, 삭제가능(수식유지시 느림) | I20: FLDT | J20: =SUMIF(Tbl_Budget[해당],TRUE,Tbl_Budget[Budget 합계]) -> 348 | K20: =SUMIF(Tbl_Budget[해당],TRUE,Tbl_Budget[1]) -> 0 | L20: =SUMIF(Tbl_Budget[해당],TRUE,Tbl_Budget[2]) -> 0 | M20: =SUMIF(Tbl_Budget[해당],TRUE,Tbl_Budget[3]) -> 53 | N20: =SUMIF(Tbl_Budget[해당],TRUE,Tbl_Budget[4]) -> 0 | O20: =SUMIF(Tbl_Budget[해당],TRUE,Tbl_Budget[5]) -> 0 | P20: =SUMIF(Tbl_Budget[해당],TRUE,Tbl_Budget[6]) -> 34 | Q20: =SUMIF(Tbl_Budget[해당],TRUE,Tbl_Budget[7]) -> 0 | R20: =SUMIF(Tbl_Budget[해당],TRUE,Tbl_Budget[8]) -> 0 | S20: =SUMIF(Tbl_Budget[해당],TRUE,Tbl_Budget[9]) -> 96 | T20: =SUMIF(Tbl_Budget[해당],TRUE,Tbl_Budget[10]) -> 145 | U20: =SUMIF(Tbl_Budget[해당],TRUE,Tbl_Budget[11]) -> 20 | V20: =SUMIF(Tbl_Budget[해당],TRUE,Tbl_Budget[12]) -> 0 | X20: =SUM(T20:V20)/C9 -> 0.47413793 | Y20: ET 전체 기말비율
B21: 대분류 명 | C21: Budget 관리단위 | D21: 해당 | E21: 25/06 Debriefing 실적 | F21: 유사회사 평균 비율 | G21: 유사회사 평균비율 적용 시 산출 시간 | H21: Assignment | I21: 사번 | J21: Budget 합계 | K21: ='B_ET 기본정보'!C14 -> 45748 | L21: =EDATE(K21,1) -> 45778 | M21: =EDATE(L21,1) -> 45809 | N21: =EDATE(M21,1) -> 45839 | O21: =EDATE(N21,1) -> 45870 | P21: =EDATE(O21,1) -> 45901 | Q21: =EDATE(P21,1) -> 45931 | R21: =EDATE(Q21,1) -> 45962 | S21: =EDATE(R21,1) -> 45992 | ... V21: =EDATE(U21,1) -> 46082 | W21: 합계검증 | X21: 기말비율
B22: 대분류 명 | C22: Budget 관리단위 | D22: 해당 | E22: 25/06 Debriefing실적 | F22: 유사회사 평균 비율 | G22: 유사회사평균비율 적용 시 산출 시간 | H22: Assignment | I22: 사번 | J22: Budget 합계 | K22: 1 | L22: 2 | M22: 3 | N22: 4 | O22: 5 | P22: 6 | Q22: 7 | R22: 8 | S22: 9 | T22: 10 | U22: 11 | V22: 12 | W22: 합계검증 | X22: 기말비율
B23: 분반기 검토 | C23: 분반기 검토 | D23: FALSE | F23: {=IFERROR(INDEX(DB_tStat!$A$2:$DQ$111, _xlfn.XMATCH($F$20, DB_tStat!$A$2:$A$111, 0), _xlfn.XMATCH(Tbl_Budget[[#This Row],[Budget 관리단위]], DB_tStat!$A$1:$DQ$1, 0)),0)} -> 0.1226388 | G23: =Tbl_Budget[[#This Row],[유사회사 평균 비율]]*$C$9 -> 42.678301 | I23: =_xlfn.XLOOKUP(Tbl_Budget[[#This Row],[Assignment]],Tbl_Members[이름],Tbl_Members[사번],0) -> 0 | W23: =IF(Tbl_Budget[[#This Row],[해당]]=TRUE,Tbl_Budget[[#This Row],[Budget 합계]]-SUM(Tbl_Budget[[#This Row],[1]:[12]]),0) -> 0 | X23: =SUM(Tbl_Budget[[#This Row],[10]:[12]])/$C$13 -> 0
B24: 계획단계 | C24: 계획단계 | D24: TRUE | F24: {=IFERROR(INDEX(DB_tStat!$A$2:$DQ$111, _xlfn.XMATCH($F$20, DB_tStat!$A$2:$A$111, 0), _xlfn.XMATCH(Tbl_Budget[[#This Row],[Budget 관리단위]], DB_tStat!$A$1:$DQ$1, 0)),0)} -> 0.053405357 | G24: =Tbl_Budget[[#This Row],[유사회사 평균 비율]]*$C$9 -> 18.585064 | H24: 서보경 | I24: =_xlfn.XLOOKUP(Tbl_Budget[[#This Row],[Assignment]],Tbl_Members[이름],Tbl_Members[사번],0) -> 260666 | J24: 1 | M24: 1 | W24: =IF(Tbl_Budget[[#This Row],[해당]]=TRUE,Tbl_Budget[[#This Row],[Budget 합계]]-SUM(Tbl_Budget[[#This Row],[1]:[12]]),0) -> 0 | X24: =SUM(Tbl_Budget[[#This Row],[10]:[12]])/$C$13 -> 0
B25: 계획단계 | C25: 계획단계 | D25: TRUE | F25: {=IFERROR(INDEX(DB_tStat!$A$2:$DQ$111, _xlfn.XMATCH($F$20, DB_tStat!$A$2:$A$111, 0), _xlfn.XMATCH(Tbl_Budget[[#This Row],[Budget 관리단위]], DB_tStat!$A$1:$DQ$1, 0)),0)} -> 0.053405357 | G25: =Tbl_Budget[[#This Row],[유사회사 평균 비율]]*$C$9 -> 18.585064 | H25: 이채연 | I25: =_xlfn.XLOOKUP(Tbl_Budget[[#This Row],[Assignment]],Tbl_Members[이름],Tbl_Members[사번],0) -> 310625 | J25: 8 | M25: 8 | W25: =IF(Tbl_Budget[[#This Row],[해당]]=TRUE,Tbl_Budget[[#This Row],[Budget 합계]]-SUM(Tbl_Budget[[#This Row],[1]:[12]]),0) -> 0 | X25: =SUM(Tbl_Budget[[#This Row],[10]:[12]])/$C$13 -> 0
B26: 계획단계 | C26: 계획단계 | D26: TRUE | F26: {=IFERROR(INDEX(DB_tStat!$A$2:$DQ$111, _xlfn.XMATCH($F$20, DB_tStat!$A$2:$A$111, 0), _xlfn.XMATCH(Tbl_Budget[[#This Row],[Budget 관리단위]], DB_tStat!$A$1:$DQ$1, 0)),0)} -> 0.053405357 | G26: =Tbl_Budget[[#This Row],[유사회사 평균 비율]]*$C$9 -> 18.585064 | H26: 최우금 | I26: =_xlfn.XLOOKUP(Tbl_Budget[[#This Row],[Assignment]],Tbl_Members[이름],Tbl_Members[사번],0) -> 330590 | J26: 8 | M26: 8 | W26: =IF(Tbl_Budget[[#This Row],[해당]]=TRUE,Tbl_Budget[[#This Row],[Budget 합계]]-SUM(Tbl_Budget[[#This Row],[1]:[12]]),0) -> 0 | X26: =SUM(Tbl_Budget[[#This Row],[10]:[12]])/$C$13 -> 0
B27: 계획단계 | C27: 계획단계 | D27: TRUE | F27: {=IFERROR(INDEX(DB_tStat!$A$2:$DQ$111, _xlfn.XMATCH($F$20, DB_tStat!$A$2:$A$111, 0), _xlfn.XMATCH(Tbl_Budget[[#This Row],[Budget 관리단위]], DB_tStat!$A$1:$DQ$1, 0)),0)} -> 0.053405357 | G27: =Tbl_Budget[[#This Row],[유사회사 평균 비율]]*$C$9 -> 18.585064 | H27: 정다희 | I27: =_xlfn.XLOOKUP(Tbl_Budget[[#This Row],[Assignment]],Tbl_Members[이름],Tbl_Members[사번],0) -> 340644 | J27: 8 | M27: 8 | W27: =IF(Tbl_Budget[[#This Row],[해당]]=TRUE,Tbl_Budget[[#This Row],[Budget 합계]]-SUM(Tbl_Budget[[#This Row],[1]:[12]]),0) -> 0 | X27: =SUM(Tbl_Budget[[#This Row],[10]:[12]])/$C$13 -> 0
B28: 계획단계 | C28: 초도감사 | D28: TRUE | F28: {=IFERROR(INDEX(DB_tStat!$A$2:$DQ$111, _xlfn.XMATCH($F$20, DB_tStat!$A$2:$A$111, 0), _xlfn.XMATCH(Tbl_Budget[[#This Row],[Budget 관리단위]], DB_tStat!$A$1:$DQ$1, 0)),0)} -> 0.0073570318 | G28: =Tbl_Budget[[#This Row],[유사회사 평균 비율]]*$C$9 -> 2.5602471 | H28: 이채연 | I28: =_xlfn.XLOOKUP(Tbl_Budget[[#This Row],[Assignment]],Tbl_Members[이름],Tbl_Members[사번],0) -> 310625 | J28: 5 | M28: 5 | W28: =IF(Tbl_Budget[[#This Row],[해당]]=TRUE,Tbl_Budget[[#This Row],[Budget 합계]]-SUM(Tbl_Budget[[#This Row],[1]:[12]]),0) -> 0 | X28: =SUM(Tbl_Budget[[#This Row],[10]:[12]])/$C$13 -> 0
B29: 계획단계 | C29: 초도감사 | D29: TRUE | F29: {=IFERROR(INDEX(DB_tStat!$A$2:$DQ$111, _xlfn.XMATCH($F$20, DB_tStat!$A$2:$A$111, 0), _xlfn.XMATCH(Tbl_Budget[[#This Row],[Budget 관리단위]], DB_tStat!$A$1:$DQ$1, 0)),0)} -> 0.0073570318 | G29: =Tbl_Budget[[#This Row],[유사회사 평균 비율]]*$C$9 -> 2.5602471 | H29: 정다희 | I29: =_xlfn.XLOOKUP(Tbl_Budget[[#This Row],[Assignment]],Tbl_Members[이름],Tbl_Members[사번],0) -> 340644 | J29: 4 | M29: 4 | W29: =IF(Tbl_Budget[[#This Row],[해당]]=TRUE,Tbl_Budget[[#This Row],[Budget 합계]]-SUM(Tbl_Budget[[#This Row],[1]:[12]]),0) -> 0 | X29: =SUM(Tbl_Budget[[#This Row],[10]:[12]])/$C$13 -> 0
B30: 재무제표 수준 위험 | C30: 부정위험 | D30: TRUE | F30: {=IFERROR(INDEX(DB_tStat!$A$2:$DQ$111, _xlfn.XMATCH($F$20, DB_tStat!$A$2:$A$111, 0), _xlfn.XMATCH(Tbl_Budget[[#This Row],[Budget 관리단위]], DB_tStat!$A$1:$DQ$1, 0)),0)} -> 0.022274542 | G30: =Tbl_Budget[[#This Row],[유사회사 평균 비율]]*$C$9 -> 7.7515405 | H30: 이채연 | I30: =_xlfn.XLOOKUP(Tbl_Budget[[#This Row],[Assignment]],Tbl_Members[이름],Tbl_Members[사번],0) -> 310625 | J30: 8 | S30: 2 | T30: 6 | W30: =IF(Tbl_Budget[[#This Row],[해당]]=TRUE,Tbl_Budget[[#This Row],[Budget 합계]]-SUM(Tbl_Budget[[#This Row],[1]:[12]]),0) -> 0 | X30: =SUM(Tbl_Budget[[#This Row],[10]:[12]])/$C$13 -> 0.01744186
B31: 재무제표 수준 위험 | C31: 부정위험 | D31: TRUE | F31: {=IFERROR(INDEX(DB_tStat!$A$2:$DQ$111, _xlfn.XMATCH($F$20, DB_tStat!$A$2:$A$111, 0), _xlfn.XMATCH(Tbl_Budget[[#This Row],[Budget 관리단위]], DB_tStat!$A$1:$DQ$1, 0)),0)} -> 0.022274542 | G31: =Tbl_Budget[[#This Row],[유사회사 평균 비율]]*$C$9 -> 7.7515405 | H31: Specialist | I31: =_xlfn.XLOOKUP(Tbl_Budget[[#This Row],[Assignment]],Tbl_Members[이름],Tbl_Members[사번],0) -> Specialist | J31: 4 | T31: 4 | W31: =IF(Tbl_Budget[[#This Row],[해당]]=TRUE,Tbl_Budget[[#This Row],[Budget 합계]]-SUM(Tbl_Budget[[#This Row],[1]:[12]]),0) -> 0 | X31: =SUM(Tbl_Budget[[#This Row],[10]:[12]])/$C$13 -> 0.011627907
B32: 재무제표 수준 위험 | C32: 계속기업 | D32: FALSE | F32: {=IFERROR(INDEX(DB_tStat!$A$2:$DQ$111, _xlfn.XMATCH($F$20, DB_tStat!$A$2:$A$111, 0), _xlfn.XMATCH(Tbl_Budget[[#This Row],[Budget 관리단위]], DB_tStat!$A$1:$DQ$1, 0)),0)} -> 0.0043106812 | G32: =Tbl_Budget[[#This Row],[유사회사 평균 비율]]*$C$9 -> 1.500117 | I32: =_xlfn.XLOOKUP(Tbl_Budget[[#This Row],[Assignment]],Tbl_Members[이름],Tbl_Members[사번],0) -> 0 | W32: =IF(Tbl_Budget[[#This Row],[해당]]=TRUE,Tbl_Budget[[#This Row],[Budget 합계]]-SUM(Tbl_Budget[[#This Row],[1]:[12]]),0) -> 0 | X32: =SUM(Tbl_Budget[[#This Row],[10]:[12]])/$C$13 -> 0
B33: 재무제표 수준 위험 | C33: 기타(특수관계자/법률 및 규정) | D33: FALSE | F33: {=IFERROR(INDEX(DB_tStat!$A$2:$DQ$111, _xlfn.XMATCH($F$20, DB_tStat!$A$2:$A$111, 0), _xlfn.XMATCH(Tbl_Budget[[#This Row],[Budget 관리단위]], DB_tStat!$A$1:$DQ$1, 0)),0)} -> 0 | G33: =Tbl_Budget[[#This Row],[유사회사 평균 비율]]*$C$9 -> 0 | I33: =_xlfn.XLOOKUP(Tbl_Budget[[#This Row],[Assignment]],Tbl_Members[이름],Tbl_Members[사번],0) -> 0 | W33: =IF(Tbl_Budget[[#This Row],[해당]]=TRUE,Tbl_Budget[[#This Row],[Budget 합계]]-SUM(Tbl_Budget[[#This Row],[1]:[12]]),0) -> 0 | X33: =SUM(Tbl_Budget[[#This Row],[10]:[12]])/$C$13 -> 0
B34: 자산 | C34: 현금및현금성자산-일반 | D34: TRUE | F34: {=IFERROR(INDEX(DB_tStat!$A$2:$DQ$111, _xlfn.XMATCH($F$20, DB_tStat!$A$2:$A$111, 0), _xlfn.XMATCH(Tbl_Budget[[#This Row],[Budget 관리단위]], DB_tStat!$A$1:$DQ$1, 0)),0)} -> 0.013624565 | G34: =Tbl_Budget[[#This Row],[유사회사 평균 비율]]*$C$9 -> 4.7413485 | H34: 정다희 | I34: =_xlfn.XLOOKUP(Tbl_Budget[[#This Row],[Assignment]],Tbl_Members[이름],Tbl_Members[사번],0) -> 340644 | J34: 8 | M34: 2 | T34: 6 | W34: =IF(Tbl_Budget[[#This Row],[해당]]=TRUE,Tbl_Budget[[#This Row],[Budget 합계]]-SUM(Tbl_Budget[[#This Row],[1]:[12]]),0) -> 0 | X34: =SUM(Tbl_Budget[[#This Row],[10]:[12]])/$C$13 -> 0.01744186
B35: 자산 | C35: 현금및현금성자산-조회 | D35: TRUE | F35: {=IFERROR(INDEX(DB_tStat!$A$2:$DQ$111, _xlfn.XMATCH($F$20, DB_tStat!$A$2:$A$111, 0), _xlfn.XMATCH(Tbl_Budget[[#This Row],[Budget 관리단위]], DB_tStat!$A$1:$DQ$1, 0)),0)} -> 0.024644451 | G35: =Tbl_Budget[[#This Row],[유사회사 평균 비율]]*$C$9 -> 8.5762691 | H35: 정다희 | I35: =_xlfn.XLOOKUP(Tbl_Budget[[#This Row],[Assignment]],Tbl_Members[이름],Tbl_Members[사번],0) -> 340644 | J35: 16 | S35: 1 | T35: 15 | W35: =IF(Tbl_Budget[[#This Row],[해당]]=TRUE,Tbl_Budget[[#This Row],[Budget 합계]]-SUM(Tbl_Budget[[#This Row],[1]:[12]]),0) -> 0 | X35: =SUM(Tbl_Budget[[#This Row],[10]:[12]])/$C$13 -> 0.043604651
B36: 자산 | C36: 채무 및 지분증권-일반 | D36: FALSE | F36: {=IFERROR(INDEX(DB_tStat!$A$2:$DQ$111, _xlfn.XMATCH($F$20, DB_tStat!$A$2:$A$111, 0), _xlfn.XMATCH(Tbl_Budget[[#This Row],[Budget 관리단위]], DB_tStat!$A$1:$DQ$1, 0)),0)} -> 0.0060371235 | G36: =Tbl_Budget[[#This Row],[유사회사 평균 비율]]*$C$9 -> 2.100919 | I36: =_xlfn.XLOOKUP(Tbl_Budget[[#This Row],[Assignment]],Tbl_Members[이름],Tbl_Members[사번],0) -> 0 | W36: =IF(Tbl_Budget[[#This Row],[해당]]=TRUE,Tbl_Budget[[#This Row],[Budget 합계]]-SUM(Tbl_Budget[[#This Row],[1]:[12]]),0) -> 0 | X36: =SUM(Tbl_Budget[[#This Row],[10]:[12]])/$C$13 -> 0
B37: 자산 | C37: 채무 및 지분증권-공정가치평가 | D37: FALSE | F37: {=IFERROR(INDEX(DB_tStat!$A$2:$DQ$111, _xlfn.XMATCH($F$20, DB_tStat!$A$2:$A$111, 0), _xlfn.XMATCH(Tbl_Budget[[#This Row],[Budget 관리단위]], DB_tStat!$A$1:$DQ$1, 0)),0)} -> 0.007981138 | G37: =Tbl_Budget[[#This Row],[유사회사 평균 비율]]*$C$9 -> 2.777436 | I37: =_xlfn.XLOOKUP(Tbl_Budget[[#This Row],[Assignment]],Tbl_Members[이름],Tbl_Members[사번],0) -> 0 | W37: =IF(Tbl_Budget[[#This Row],[해당]]=TRUE,Tbl_Budget[[#This Row],[Budget 합계]]-SUM(Tbl_Budget[[#This Row],[1]:[12]]),0) -> 0 | X37: =SUM(Tbl_Budget[[#This Row],[10]:[12]])/$C$13 -> 0
B38: 자산 | C38: 파생상품 | D38: FALSE | F38: {=IFERROR(INDEX(DB_tStat!$A$2:$DQ$111, _xlfn.XMATCH($F$20, DB_tStat!$A$2:$A$111, 0), _xlfn.XMATCH(Tbl_Budget[[#This Row],[Budget 관리단위]], DB_tStat!$A$1:$DQ$1, 0)),0)} -> 0.0088320469 | G38: =Tbl_Budget[[#This Row],[유사회사 평균 비율]]*$C$9 -> 3.0735523 | I38: =_xlfn.XLOOKUP(Tbl_Budget[[#This Row],[Assignment]],Tbl_Members[이름],Tbl_Members[사번],0) -> 0 | W38: =IF(Tbl_Budget[[#This Row],[해당]]=TRUE,Tbl_Budget[[#This Row],[Budget 합계]]-SUM(Tbl_Budget[[#This Row],[1]:[12]]),0) -> 0 | X38: =SUM(Tbl_Budget[[#This Row],[10]:[12]])/$C$13 -> 0
B39: 자산 | C39: 매출채권-일반 | D39: TRUE | F39: {=IFERROR(INDEX(DB_tStat!$A$2:$DQ$111, _xlfn.XMATCH($F$20, DB_tStat!$A$2:$A$111, 0), _xlfn.XMATCH(Tbl_Budget[[#This Row],[Budget 관리단위]], DB_tStat!$A$1:$DQ$1, 0)),0)} -> 0.014714847 | G39: =Tbl_Budget[[#This Row],[유사회사 평균 비율]]*$C$9 -> 5.1207666 | H39: 이채연 | I39: =_xlfn.XLOOKUP(Tbl_Budget[[#This Row],[Assignment]],Tbl_Members[이름],Tbl_Members[사번],0) -> 310625 | J39: 10 | M39: 2 | S39: 2 | T39: 6 | W39: =IF(Tbl_Budget[[#This Row],[해당]]=TRUE,Tbl_Budget[[#This Row],[Budget 합계]]-SUM(Tbl_Budget[[#This Row],[1]:[12]]),0) -> 0 | X39: =SUM(Tbl_Budget[[#This Row],[10]:[12]])/$C$13 -> 0.01744186
B40: 자산 | C40: 매출채권-조회 | D40: TRUE | F40: {=IFERROR(INDEX(DB_tStat!$A$2:$DQ$111, _xlfn.XMATCH($F$20, DB_tStat!$A$2:$A$111, 0), _xlfn.XMATCH(Tbl_Budget[[#This Row],[Budget 관리단위]], DB_tStat!$A$1:$DQ$1, 0)),0)} -> 0.012485595 | G40: =Tbl_Budget[[#This Row],[유사회사 평균 비율]]*$C$9 -> 4.344987 | H40: 이채연 | I40: =_xlfn.XLOOKUP(Tbl_Budget[[#This Row],[Assignment]],Tbl_Members[이름],Tbl_Members[사번],0) -> 310625 | J40: 12 | S40: 3 | T40: 9 | W40: =IF(Tbl_Budget[[#This Row],[해당]]=TRUE,Tbl_Budget[[#This Row],[Budget 합계]]-SUM(Tbl_Budget[[#This Row],[1]:[12]]),0) -> 0 | X40: =SUM(Tbl_Budget[[#This Row],[10]:[12]])/$C$13 -> 0.026162791
B41: 자산 | C41: 고객 반품, 할인 및 충당금 | D41: TRUE | F41: {=IFERROR(INDEX(DB_tStat!$A$2:$DQ$111, _xlfn.XMATCH($F$20, DB_tStat!$A$2:$A$111, 0), _xlfn.XMATCH(Tbl_Budget[[#This Row],[Budget 관리단위]], DB_tStat!$A$1:$DQ$1, 0)),0)} -> 0.0045228391 | G41: =Tbl_Budget[[#This Row],[유사회사 평균 비율]]*$C$9 -> 1.573948 | H41: 이채연 | I41: =_xlfn.XLOOKUP(Tbl_Budget[[#This Row],[Assignment]],Tbl_Members[이름],Tbl_Members[사번],0) -> 310625 | J41: 12 | M41: 2 | S41: 4 | T41: 6 | W41: =IF(Tbl_Budget[[#This Row],[해당]]=TRUE,Tbl_Budget[[#This Row],[Budget 합계]]-SUM(Tbl_Budget[[#This Row],[1]:[12]]),0) -> 0 | X41: =SUM(Tbl_Budget[[#This Row],[10]:[12]])/$C$13 -> 0.01744186
...

Sheet F_표준감사시간
A1: ='B_ET 기본정보'!C20 -> 15916-01-012 | B1: ='B_ET 기본정보'!C21 -> (주)에뛰드/2025년 회계감사 | D1: =IFERROR(('D_2606 budget template'!C4+'D_2606 budget template'!C14)/('D_2606 budget template'!C13-'D_2606 budget template'!C14),0) -> 0.22383721 | E1: ='D_2606 budget template'!C3-SUMIFS(Tbl_Budget[Budget 합계],Tbl_Budget[Budget 관리단위],"외국어 보고서",Tbl_Budget[해당],TRUE) -> 500 | F1: 검증 | G1: =E1-K4 -> 0 | H1: ='D_2606 budget template'!C13+'D_2606 budget template'!C4-SUM(K12:K484)-SUMIFS(Tbl_Budget[Budget 합계],Tbl_Budget[Budget 관리단위],"외국어 보고서",Tbl_Budget[해당],TRUE) -> 0 | K1: Monthly | L1: 1 | M1: 2 | N1: 3 | O1: 4 | P1: 5 | Q1: 6 | R1: 7 | S1: 8 | T1: 9 | U1: 10 | V1: 11 | W1: 12 | X1: 39 | Y1: 40 | Z1: 41 | AA1: 42 | AB1: 43 | AC1: 44 | AD1: 45 | AE1: 46 | AF1: 47 | AG1: 48 | AH1: 49 | AI1: 50 | AJ1: 51 | AK1: 52 | AL1: 53 | AM1: 54 | AN1: 55 | AO1: 56 | AP1: 57 | AQ1: 58 | AR1: 59 | AS1: 60 | AT1: 61
A2: Project Code | B2: Project Name | C2: TBD | D2: Activity | E2: Location | F2: Name | G2: 사번 | H2: Grade | I2: 숙련도 | J2: 숙련도 고려투입시간 | K2: TotalTime | L2: =TEXT('D_2606 budget template'!K21,"YYYY/MM") -> 2025/04 | M2: =TEXT('D_2606 budget template'!L21,"YYYY/MM") -> 2025/05 | N2: =TEXT('D_2606 budget template'!M21,"YYYY/MM") -> 2025/06 | O2: =TEXT('D_2606 budget template'!N21,"YYYY/MM") -> 2025/07 | P2: =TEXT('D_2606 budget template'!O21,"YYYY/MM") -> 2025/08 | Q2: =TEXT('D_2606 budget template'!P21,"YYYY/MM") -> 2025/09 | R2: =TEXT('D_2606 budget template'!Q21,"YYYY/MM") -> 2025/10 | S2: =TEXT('D_2606 budget template'!R21,"YYYY/MM") -> 2025/11 | ... W2: =TEXT('D_2606 budget template'!V21,"YYYY/MM") -> 2026/03
L3: =TEXT(NETWORKDAYS(EOMONTH(L2,-1)+1,EOMONTH(L2,0)),"##0")&" days" -> 22 days | M3: =TEXT(NETWORKDAYS(EOMONTH(M2,-1)+1,EOMONTH(M2,0)),"##0")&" days" -> 22 days | N3: =TEXT(NETWORKDAYS(EOMONTH(N2,-1)+1,EOMONTH(N2,0)),"##0")&" days" -> 21 days | O3: =TEXT(NETWORKDAYS(EOMONTH(O2,-1)+1,EOMONTH(O2,0)),"##0")&" days" -> 23 days | P3: =TEXT(NETWORKDAYS(EOMONTH(P2,-1)+1,EOMONTH(P2,0)),"##0")&" days" -> 21 days | Q3: =TEXT(NETWORKDAYS(EOMONTH(Q2,-1)+1,EOMONTH(Q2,0)),"##0")&" days" -> 22 days | R3: =TEXT(NETWORKDAYS(EOMONTH(R2,-1)+1,EOMONTH(R2,0)),"##0")&" days" -> 23 days | S3: =TEXT(NETWORKDAYS(EOMONTH(S2,-1)+1,EOMONTH(S2,0)),"##0")&" days" -> 20 days | ... W3: =TEXT(NETWORKDAYS(EOMONTH(W2,-1)+1,EOMONTH(W2,0)),"##0")&" days" -> 22 days
A4: (필수)프로젝트 코드 입력 | B4: 옵션 | C4: (필수)목록에서 선택 | D4: (필수)목록에서 선택 | E4: (필수)목록에서 선택 | F4: 옵션 | G4: 옵션 | H4: 옵션 | I4: =IF(K4=0, 0, J4/K4) -> 0 | J4: =SUM(J5:J484) -> 0 | K4: =SUM(K5:K484) -> 500 | L4: =SUM(L5:L484) -> 0 | M4: =SUM(M5:M484) -> 0 | N4: =SUM(N5:N484) -> 65 | O4: =SUM(O5:O484) -> 0 | P4: =SUM(P5:P484) -> 0 | Q4: =SUM(Q5:Q484) -> 41 | ... AT4: =SUM(AT5:AT484) -> 0
A5: =$A$1 -> 15916-01-012 | B5: =$B$1 -> (주)에뛰드/2025년 회계감사 | C5: N | D5: 재무제표기말감사 | E5: Field | G5: ='B_ET 기본정보'!D23 -> 170661 | J5: =I5*K5 -> 0 | K5: =SUM(L5:AT5) -> 20 | W5: ='B_ET 기본정보'!C31 -> 20
A6: =$A$1 -> 15916-01-012 | B6: =$B$1 -> (주)에뛰드/2025년 회계감사 | C6: N | D6: 재무제표기말감사 | E6: Field | G6: ='B_ET 기본정보'!D24 -> 280570 | J6: =I6*K6 -> 0 | K6: =SUM(L6:AT6) -> 55 | W6: ='B_ET 기본정보'!C32+H1 -> 55
A7: =$A$1 -> 15916-01-012 | B7: =$B$1 -> (주)에뛰드/2025년 회계감사 | C7: Y | D7: QRP | E7: Non-Field | H7: Partner | J7: =I7*K7 -> 0 | K7: =SUM(L7:AT7) -> 0 | W7: ='B_ET 기본정보'!C29 -> 0
A8: =$A$1 -> 15916-01-012 | B8: =$B$1 -> (주)에뛰드/2025년 회계감사 | C8: Y | D8: QC-(RM, ACS, M&T 등) | E8: Non-Field | H8: Director | J8: =I8*K8 -> 0 | K8: =SUM(L8:AT8) -> 0 | W8: ='B_ET 기본정보'!C30 -> 0
A9: =$A$1 -> 15916-01-012 | B9: =$B$1 -> (주)에뛰드/2025년 회계감사 | C9: Y | D9: SPA_내부통제 | E9: Non-Field | H9: Senior-Associate | J9: =I9*K9 -> 0 | K9: =SUM(L9:AT9) -> 0 | W9: ='B_ET 기본정보'!C33+'D_2606 budget template'!C11 -> 0
A10: =$A$1 -> 15916-01-012 | B10: =$B$1 -> (주)에뛰드/2025년 회계감사 | C10: Y | D10: Fulcrum | E10: Non-Field | H10: Senior-Associate | J10: =I10*K10 -> 0 | K10: =SUM(L10:AT10) -> 0 | W10: ='D_2606 budget template'!C10 -> 0
A11: =$A$1 -> 15916-01-012 | B11: =$B$1 -> (주)에뛰드/2025년 회계감사 | C11: Y | D11: 기타 | E11: Non-Field | H11: Senior-Associate | J11: =I11*K11 -> 0 | K11: =SUM(L11:AT11) -> 4 | W11: ='D_2606 budget template'!C12 -> 4
A12: =$A$1 -> 15916-01-012 | B12: =$B$1 -> (주)에뛰드/2025년 회계감사 | C12: Y | D12: 재무제표기말감사 | E12: Field | H12: Manager | J12: =I12*K12 -> 0 | K12: =SUM(L12:AT12) -> 0 | L12: =IFERROR(ROUND(SUMIFS(Tbl_Budget[1],Tbl_Budget[사번], "*TBD_Manager*",Tbl_Budget[해당],TRUE,Tbl_Budget[Budget 관리단위],"<>외국어 보고서")*(1+$D$1),),0) -> 0 | M12: =IFERROR(ROUND(SUMIFS(Tbl_Budget[2],Tbl_Budget[사번], "*TBD_Manager*",Tbl_Budget[해당],TRUE,Tbl_Budget[Budget 관리단위],"<>외국어 보고서")*(1+$D$1),),0) -> 0 | N12: =IFERROR(ROUND(SUMIFS(Tbl_Budget[3],Tbl_Budget[사번], "*TBD_Manager*",Tbl_Budget[해당],TRUE,Tbl_Budget[Budget 관리단위],"<>외국어 보고서")*(1+$D$1),),0) -> 0 | O12: =IFERROR(ROUND(SUMIFS(Tbl_Budget[4],Tbl_Budget[사번], "*TBD_Manager*",Tbl_Budget[해당],TRUE,Tbl_Budget[Budget 관리단위],"<>외국어 보고서")*(1+$D$1),),0) -> 0 | P12: =IFERROR(ROUND(SUMIFS(Tbl_Budget[5],Tbl_Budget[사번], "*TBD_Manager*",Tbl_Budget[해당],TRUE,Tbl_Budget[Budget 관리단위],"<>외국어 보고서")*(1+$D$1),),0) -> 0 | Q12: =IFERROR(ROUND(SUMIFS(Tbl_Budget[6],Tbl_Budget[사번], "*TBD_Manager*",Tbl_Budget[해당],TRUE,Tbl_Budget[Budget 관리단위],"<>외국어 보고서")*(1+$D$1),),0) -> 0 | R12: =IFERROR(ROUND(SUMIFS(Tbl_Budget[7],Tbl_Budget[사번], "*TBD_Manager*",Tbl_Budget[해당],TRUE,Tbl_Budget[Budget 관리단위],"<>외국어 보고서")*(1+$D$1),),0) -> 0 | S12: =IFERROR(ROUND(SUMIFS(Tbl_Budget[8],Tbl_Budget[사번], "*TBD_Manager*",Tbl_Budget[해당],TRUE,Tbl_Budget[Budget 관리단위],"<>외국어 보고서")*(1+$D$1),),0) -> 0 | T12: =IFERROR(ROUND(SUMIFS(Tbl_Budget[9],Tbl_Budget[사번], "*TBD_Manager*",Tbl_Budget[해당],TRUE,Tbl_Budget[Budget 관리단위],"<>외국어 보고서")*(1+$D$1),),0) -> 0 | U12: =IFERROR(ROUND(SUMIFS(Tbl_Budget[10],Tbl_Budget[사번], "*TBD_Manager*",Tbl_Budget[해당],TRUE,Tbl_Budget[Budget 관리단위],"<>외국어 보고서")*(1+$D$1),),0) -> 0 | V12: =IFERROR(ROUND(SUMIFS(Tbl_Budget[11],Tbl_Budget[사번], "*TBD_Manager*",Tbl_Budget[해당],TRUE,Tbl_Budget[Budget 관리단위],"<>외국어 보고서")*(1+$D$1),),0) -> 0 | W12: =IFERROR(ROUND(SUMIFS(Tbl_Budget[12],Tbl_Budget[사번], "*TBD_Manager*",Tbl_Budget[해당],TRUE,Tbl_Budget[Budget 관리단위],"<>외국어 보고서")*(1+$D$1),),0) -> 0
A13: =$A$1 -> 15916-01-012 | B13: =$B$1 -> (주)에뛰드/2025년 회계감사 | C13: Y | D13: 재무제표기말감사 | E13: Field | H13: Senior-Associate | J13: =I13*K13 -> 0 | K13: =SUM(L13:AT13) -> 0 | L13: =IFERROR(ROUND(SUMIFS(Tbl_Budget[1],Tbl_Budget[사번], "*TBD_Senior-Associate*",Tbl_Budget[해당],TRUE,Tbl_Budget[Budget 관리단위],"<>외국어 보고서")*(1+$D$1),),0) -> 0 | M13: =IFERROR(ROUND(SUMIFS(Tbl_Budget[2],Tbl_Budget[사번], "*TBD_Senior-Associate*",Tbl_Budget[해당],TRUE,Tbl_Budget[Budget 관리단위],"<>외국어 보고서")*(1+$D$1),),0) -> 0 | N13: =IFERROR(ROUND(SUMIFS(Tbl_Budget[3],Tbl_Budget[사번], "*TBD_Senior-Associate*",Tbl_Budget[해당],TRUE,Tbl_Budget[Budget 관리단위],"<>외국어 보고서")*(1+$D$1),),0) -> 0 | O13: =IFERROR(ROUND(SUMIFS(Tbl_Budget[4],Tbl_Budget[사번], "*TBD_Senior-Associate*",Tbl_Budget[해당],TRUE,Tbl_Budget[Budget 관리단위],"<>외국어 보고서")*(1+$D$1),),0) -> 0 | P13: =IFERROR(ROUND(SUMIFS(Tbl_Budget[5],Tbl_Budget[사번], "*TBD_Senior-Associate*",Tbl_Budget[해당],TRUE,Tbl_Budget[Budget 관리단위],"<>외국어 보고서")*(1+$D$1),),0) -> 0 | Q13: =IFERROR(ROUND(SUMIFS(Tbl_Budget[6],Tbl_Budget[사번], "*TBD_Senior-Associate*",Tbl_Budget[해당],TRUE,Tbl_Budget[Budget 관리단위],"<>외국어 보고서")*(1+$D$1),),0) -> 0 | R13: =IFERROR(ROUND(SUMIFS(Tbl_Budget[7],Tbl_Budget[사번], "*TBD_Senior-Associate*",Tbl_Budget[해당],TRUE,Tbl_Budget[Budget 관리단위],"<>외국어 보고서")*(1+$D$1),),0) -> 0 | S13: =IFERROR(ROUND(SUMIFS(Tbl_Budget[8],Tbl_Budget[사번], "*TBD_Senior-Associate*",Tbl_Budget[해당],TRUE,Tbl_Budget[Budget 관리단위],"<>외국어 보고서")*(1+$D$1),),0) -> 0 | T13: =IFERROR(ROUND(SUMIFS(Tbl_Budget[9],Tbl_Budget[사번], "*TBD_Senior-Associate*",Tbl_Budget[해당],TRUE,Tbl_Budget[Budget 관리단위],"<>외국어 보고서")*(1+$D$1),),0) -> 0 | U13: =IFERROR(ROUND(SUMIFS(Tbl_Budget[10],Tbl_Budget[사번], "*TBD_Senior-Associate*",Tbl_Budget[해당],TRUE,Tbl_Budget[Budget 관리단위],"<>외국어 보고서")*(1+$D$1),),0) -> 0 | V13: =IFERROR(ROUND(SUMIFS(Tbl_Budget[11],Tbl_Budget[사번], "*TBD_Senior-Associate*",Tbl_Budget[해당],TRUE,Tbl_Budget[Budget 관리단위],"<>외국어 보고서")*(1+$D$1),),0) -> 0 | W13: =IFERROR(ROUND(SUMIFS(Tbl_Budget[12],Tbl_Budget[사번], "*TBD_Senior-Associate*",Tbl_Budget[해당],TRUE,Tbl_Budget[Budget 관리단위],"<>외국어 보고서")*(1+$D$1),),0) -> 0
A14: =$A$1 -> 15916-01-012 | B14: =$B$1 -> (주)에뛰드/2025년 회계감사 | C14: Y | D14: 재무제표기말감사 | E14: Field | H14: Associate | J14: =I14*K14 -> 0 | K14: =SUM(L14:AT14) -> 0 | L14: =IFERROR(ROUND(SUMIFS(Tbl_Budget[1],Tbl_Budget[사번], "*TBD_Associate*",Tbl_Budget[해당],TRUE,Tbl_Budget[Budget 관리단위],"<>외국어 보고서")*(1+$D$1),),0) -> 0 | M14: =IFERROR(ROUND(SUMIFS(Tbl_Budget[2],Tbl_Budget[사번], "*TBD_Associate*",Tbl_Budget[해당],TRUE,Tbl_Budget[Budget 관리단위],"<>외국어 보고서")*(1+$D$1),),0) -> 0 | N14: =IFERROR(ROUND(SUMIFS(Tbl_Budget[3],Tbl_Budget[사번], "*TBD_Associate*",Tbl_Budget[해당],TRUE,Tbl_Budget[Budget 관리단위],"<>외국어 보고서")*(1+$D$1),),0) -> 0 | O14: =IFERROR(ROUND(SUMIFS(Tbl_Budget[4],Tbl_Budget[사번], "*TBD_Associate*",Tbl_Budget[해당],TRUE,Tbl_Budget[Budget 관리단위],"<>외국어 보고서")*(1+$D$1),),0) -> 0 | P14: =IFERROR(ROUND(SUMIFS(Tbl_Budget[5],Tbl_Budget[사번], "*TBD_Associate*",Tbl_Budget[해당],TRUE,Tbl_Budget[Budget 관리단위],"<>외국어 보고서")*(1+$D$1),),0) -> 0 | Q14: =IFERROR(ROUND(SUMIFS(Tbl_Budget[6],Tbl_Budget[사번], "*TBD_Associate*",Tbl_Budget[해당],TRUE,Tbl_Budget[Budget 관리단위],"<>외국어 보고서")*(1+$D$1),),0) -> 0 | R14: =IFERROR(ROUND(SUMIFS(Tbl_Budget[7],Tbl_Budget[사번], "*TBD_Associate*",Tbl_Budget[해당],TRUE,Tbl_Budget[Budget 관리단위],"<>외국어 보고서")*(1+$D$1),),0) -> 0 | S14: =IFERROR(ROUND(SUMIFS(Tbl_Budget[8],Tbl_Budget[사번], "*TBD_Associate*",Tbl_Budget[해당],TRUE,Tbl_Budget[Budget 관리단위],"<>외국어 보고서")*(1+$D$1),),0) -> 0 | T14: =IFERROR(ROUND(SUMIFS(Tbl_Budget[9],Tbl_Budget[사번], "*TBD_Associate*",Tbl_Budget[해당],TRUE,Tbl_Budget[Budget 관리단위],"<>외국어 보고서")*(1+$D$1),),0) -> 0 | U14: =IFERROR(ROUND(SUMIFS(Tbl_Budget[10],Tbl_Budget[사번], "*TBD_Associate*",Tbl_Budget[해당],TRUE,Tbl_Budget[Budget 관리단위],"<>외국어 보고서")*(1+$D$1),),0) -> 0 | V14: =IFERROR(ROUND(SUMIFS(Tbl_Budget[11],Tbl_Budget[사번], "*TBD_Associate*",Tbl_Budget[해당],TRUE,Tbl_Budget[Budget 관리단위],"<>외국어 보고서")*(1+$D$1),),0) -> 0 | W14: =IFERROR(ROUND(SUMIFS(Tbl_Budget[12],Tbl_Budget[사번], "*TBD_Associate*",Tbl_Budget[해당],TRUE,Tbl_Budget[Budget 관리단위],"<>외국어 보고서")*(1+$D$1),),0) -> 0
A15: =$A$1 -> 15916-01-012 | B15: =$B$1 -> (주)에뛰드/2025년 회계감사 | C15: Y | D15: New Staff | E15: Field | H15: Associate | J15: =I15*K15 -> 0 | K15: =SUM(L15:AT15) -> 0 | L15: =IFERROR(ROUND(SUMIFS(Tbl_Budget[1],Tbl_Budget[사번], "*New comer*",Tbl_Budget[해당],TRUE,Tbl_Budget[Budget 관리단위],"<>외국어 보고서")*(1+$D$1),),0) -> 0 | M15: =IFERROR(ROUND(SUMIFS(Tbl_Budget[2],Tbl_Budget[사번], "*New comer*",Tbl_Budget[해당],TRUE,Tbl_Budget[Budget 관리단위],"<>외국어 보고서")*(1+$D$1),),0) -> 0 | N15: =IFERROR(ROUND(SUMIFS(Tbl_Budget[3],Tbl_Budget[사번], "*New comer*",Tbl_Budget[해당],TRUE,Tbl_Budget[Budget 관리단위],"<>외국어 보고서")*(1+$D$1),),0) -> 0 | O15: =IFERROR(ROUND(SUMIFS(Tbl_Budget[4],Tbl_Budget[사번], "*New comer*",Tbl_Budget[해당],TRUE,Tbl_Budget[Budget 관리단위],"<>외국어 보고서")*(1+$D$1),),0) -> 0 | P15: =IFERROR(ROUND(SUMIFS(Tbl_Budget[5],Tbl_Budget[사번], "*New comer*",Tbl_Budget[해당],TRUE,Tbl_Budget[Budget 관리단위],"<>외국어 보고서")*(1+$D$1),),0) -> 0 | Q15: =IFERROR(ROUND(SUMIFS(Tbl_Budget[6],Tbl_Budget[사번], "*New comer*",Tbl_Budget[해당],TRUE,Tbl_Budget[Budget 관리단위],"<>외국어 보고서")*(1+$D$1),),0) -> 0 | R15: =IFERROR(ROUND(SUMIFS(Tbl_Budget[7],Tbl_Budget[사번], "*New comer*",Tbl_Budget[해당],TRUE,Tbl_Budget[Budget 관리단위],"<>외국어 보고서")*(1+$D$1),),0) -> 0 | S15: =IFERROR(ROUND(SUMIFS(Tbl_Budget[8],Tbl_Budget[사번], "*New comer*",Tbl_Budget[해당],TRUE,Tbl_Budget[Budget 관리단위],"<>외국어 보고서")*(1+$D$1),),0) -> 0 | T15: =IFERROR(ROUND(SUMIFS(Tbl_Budget[9],Tbl_Budget[사번], "*New comer*",Tbl_Budget[해당],TRUE,Tbl_Budget[Budget 관리단위],"<>외국어 보고서")*(1+$D$1),),0) -> 0 | U15: =IFERROR(ROUND(SUMIFS(Tbl_Budget[10],Tbl_Budget[사번], "*New comer*",Tbl_Budget[해당],TRUE,Tbl_Budget[Budget 관리단위],"<>외국어 보고서")*(1+$D$1),),0) -> 0 | V15: =IFERROR(ROUND(SUMIFS(Tbl_Budget[11],Tbl_Budget[사번], "*New comer*",Tbl_Budget[해당],TRUE,Tbl_Budget[Budget 관리단위],"<>외국어 보고서")*(1+$D$1),),0) -> 0 | W15: =IFERROR(ROUND(SUMIFS(Tbl_Budget[12],Tbl_Budget[사번], "*New comer*",Tbl_Budget[해당],TRUE,Tbl_Budget[Budget 관리단위],"<>외국어 보고서")*(1+$D$1),),0) -> 0
A16: {=_xlfn.MAKEARRAY(ROWS(_xlfn.ANCHORARRAY(D16)), 1, _xlfn.LAMBDA(_xlpm.r,_xlpm.c, A1))} -> 15916-01-012 | B16: {=_xlfn.MAKEARRAY(ROWS(_xlfn.ANCHORARRAY(D16)), 1, _xlfn.LAMBDA(_xlpm.r,_xlpm.c, B1))} -> (주)에뛰드/2025년 회계감사 | C16: {=_xlfn.MAKEARRAY(ROWS(_xlfn.ANCHORARRAY(D16)), 1, _xlfn.LAMBDA(_xlpm.r,_xlpm.c, "N"))} -> N | D16: {=_xlfn.MAKEARRAY( COUNTA( _xlfn._xlws.FILTER( Tbl_Members[사번], LEN(Tbl_Members[사번])=6 ) ), 1, _xlfn.LAMBDA(_xlpm.r,_xlpm.c, "재무제표기말감사") )} -> 재무제표기말감사 | E16: {=_xlfn.MAKEARRAY(ROWS(_xlfn.ANCHORARRAY(D16)), 1, _xlfn.LAMBDA(_xlpm.r,_xlpm.c, "Field"))} -> Field | G16: {=_xlfn._xlws.FILTER( Tbl_Members[사번], LEN(Tbl_Members[사번])=6 )} -> 260666 | J16: =I16*K16 -> 0 | K16: =SUM(L16:AT16) -> 1 | L16: {=IFERROR(ROUND(SUMIFS(Tbl_Budget[1],Tbl_Budget[사번],_xlfn.ANCHORARRAY($G$16),Tbl_Budget[해당],TRUE,Tbl_Budget[Budget 관리단위],"<>외국어 보고서")*(1+$D$1),),0)} -> 0 | M16: {=IFERROR(ROUND(SUMIFS(Tbl_Budget[2],Tbl_Budget[사번],_xlfn.ANCHORARRAY($G$16),Tbl_Budget[해당],TRUE,Tbl_Budget[Budget 관리단위],"<>외국어 보고서")*(1+$D$1),),0)} -> 0 | N16: {=IFERROR(ROUND(SUMIFS(Tbl_Budget[3],Tbl_Budget[사번],_xlfn.ANCHORARRAY($G$16),Tbl_Budget[해당],TRUE,Tbl_Budget[Budget 관리단위],"<>외국어 보고서")*(1+$D$1),),0)} -> 1 | O16: {=IFERROR(ROUND(SUMIFS(Tbl_Budget[4],Tbl_Budget[사번],_xlfn.ANCHORARRAY($G$16),Tbl_Budget[해당],TRUE,Tbl_Budget[Budget 관리단위],"<>외국어 보고서")*(1+$D$1),),0)} -> 0 | P16: {=IFERROR(ROUND(SUMIFS(Tbl_Budget[5],Tbl_Budget[사번],_xlfn.ANCHORARRAY($G$16),Tbl_Budget[해당],TRUE,Tbl_Budget[Budget 관리단위],"<>외국어 보고서")*(1+$D$1),),0)} -> 0 | Q16: {=IFERROR(ROUND(SUMIFS(Tbl_Budget[6],Tbl_Budget[사번],_xlfn.ANCHORARRAY($G$16),Tbl_Budget[해당],TRUE,Tbl_Budget[Budget 관리단위],"<>외국어 보고서")*(1+$D$1),),0)} -> 0 | R16: {=IFERROR(ROUND(SUMIFS(Tbl_Budget[7],Tbl_Budget[사번],_xlfn.ANCHORARRAY($G$16),Tbl_Budget[해당],TRUE,Tbl_Budget[Budget 관리단위],"<>외국어 보고서")*(1+$D$1),),0)} -> 0 | S16: {=IFERROR(ROUND(SUMIFS(Tbl_Budget[8],Tbl_Budget[사번],_xlfn.ANCHORARRAY($G$16),Tbl_Budget[해당],TRUE,Tbl_Budget[Budget 관리단위],"<>외국어 보고서")*(1+$D$1),),0)} -> 0 | T16: {=IFERROR(ROUND(SUMIFS(Tbl_Budget[9],Tbl_Budget[사번],_xlfn.ANCHORARRAY($G$16),Tbl_Budget[해당],TRUE,Tbl_Budget[Budget 관리단위],"<>외국어 보고서")*(1+$D$1),),0)} -> 0 | U16: {=IFERROR(ROUND(SUMIFS(Tbl_Budget[10],Tbl_Budget[사번],_xlfn.ANCHORARRAY($G$16),Tbl_Budget[해당],TRUE,Tbl_Budget[Budget 관리단위],"<>외국어 보고서")*(1+$D$1),),0)} -> 0 | V16: {=IFERROR(ROUND(SUMIFS(Tbl_Budget[11],Tbl_Budget[사번],_xlfn.ANCHORARRAY($G$16),Tbl_Budget[해당],TRUE,Tbl_Budget[Budget 관리단위],"<>외국어 보고서")*(1+$D$1),),0)} -> 0 | W16: {=IFERROR(ROUND(SUMIFS(Tbl_Budget[12],Tbl_Budget[사번],_xlfn.ANCHORARRAY($G$16),Tbl_Budget[해당],TRUE,Tbl_Budget[Budget 관리단위],"<>외국어 보고서")*(1+$D$1),),0)} -> 0
A17: 15916-01-012 | B17: (주)에뛰드/2025년 회계감사 | C17: N | D17: 재무제표기말감사 | E17: Field | G17: 310625 | J17: =I17*K17 -> 0 | K17: =SUM(L17:AT17) -> 156 | L17: 0 | M17: 0 | N17: 31 | O17: 0 | P17: 0 | Q17: 15 | R17: 0 | S17: 0 | T17: 38 | U17: 48 | V17: 24 | W17: 0
A18: 15916-01-012 | B18: (주)에뛰드/2025년 회계감사 | C18: N | D18: 재무제표기말감사 | E18: Field | G18: 330590 | J18: =I18*K18 -> 0 | K18: =SUM(L18:AT18) -> 132 | L18: 0 | M18: 0 | N18: 10 | O18: 0 | P18: 0 | Q18: 13 | R18: 0 | S18: 0 | T18: 48 | U18: 61 | V18: 0 | W18: 0
A19: 15916-01-012 | B19: (주)에뛰드/2025년 회계감사 | C19: N | D19: 재무제표기말감사 | E19: Field | G19: 340644 | J19: =I19*K19 -> 0 | K19: =SUM(L19:AT19) -> 132 | L19: 0 | M19: 0 | N19: 23 | O19: 0 | P19: 0 | Q19: 13 | R19: 0 | S19: 0 | T19: 32 | U19: 64 | V19: 0 | W19: 0
J20: =I20*K20 -> 0 | K20: =SUM(L20:AT20) -> 0
J21: =I21*K21 -> 0 | K21: =SUM(L21:AT21) -> 0
J22: =I22*K22 -> 0 | K22: =SUM(L22:AT22) -> 0
J23: =I23*K23 -> 0 | K23: =SUM(L23:AT23) -> 0
J24: =I24*K24 -> 0 | K24: =SUM(L24:AT24) -> 0
J25: =I25*K25 -> 0 | K25: =SUM(L25:AT25) -> 0
J26: =I26*K26 -> 0 | K26: =SUM(L26:AT26) -> 0
J27: =I27*K27 -> 0 | K27: =SUM(L27:AT27) -> 0
J28: =I28*K28 -> 0 | K28: =SUM(L28:AT28) -> 0
J29: =I29*K29 -> 0 | K29: =SUM(L29:AT29) -> 0
J30: =I30*K30 -> 0 | K30: =SUM(L30:AT30) -> 0
J31: =I31*K31 -> 0 | K31: =SUM(L31:AT31) -> 0
... J484: =I484*K484 -> 0 | K484: =SUM(L484:AT484) -> 0

Sheet E_예산관리단위
B1: Time Report Activity 구분
B2: 대분류 코드 | C2: 대분류 명 | D2: 중분류 코드 | E2: 중분류 명 | F2: 소분류 코드 | G2: 소분류 명 | H2: Budget 관리단위 | I2: 비고
B3: Code number1 | C3: Code name1 | D3: Code number2 | E3: Code name2 | F3: Code number3 | G3: Code name3
B4: AA1000 | C4: PM/Sub PM | D4: AA1100 | E4: 감사/검토 계획 수립 | F4: AA1101 | G4: - | H4: N/A(FLDT-PM 시간)
B5: AA1000 | C5: PM/Sub PM | D5: AA1200 | E5: Client communication | F5: AA1201 | G5: - | H5: N/A(FLDT-PM 시간)
B6: AA1000 | C6: PM/Sub PM | D6: AA1300 | E6: Internal communication | F6: AA1301 | G6: - | H6: N/A(FLDT-PM 시간)
B7: AA1000 | C7: PM/Sub PM | D7: AA1400 | E7: 코칭&리뷰 | F7: AA1401 | G7: - | H7: N/A(FLDT-PM 시간)
B8: AA1000 | C8: PM/Sub PM | D8: AA1600 | E8: 감사/검토 종결 단계 | F8: AA1601 | G8: - | H8: N/A(FLDT-PM 시간)
B9: AA1000 | C9: PM/Sub PM | D9: AA1800 | E9: Admin | F9: AA1801 | G9: - | H9: N/A(FLDT-PM 시간)
B10: AA1000 | C10: PM/Sub PM | D10: AA1900 | E10: 기타 | F10: AA1901 | G10: - | H10: N/A(FLDT-PM 시간)
B11: AA10000 | C11: 분반기 검토 | D11: AA11000 | E11: 계획/준비 | F11: AA11002 | G11: Aura DB tailoring | H11: 분반기 검토
B12: AA10000 | C12: 분반기 검토 | D12: AA11000 | E12: 계획/준비 | F12: AA11010 | G12: Planning EGA 문서화 | H12: 분반기 검토
B13: AA10000 | C13: 분반기 검토 | D13: AA11000 | E13: 계획/준비 | F13: AA11015 | G13: 기타 | H13: 분반기 검토
B14: AA10000 | C14: 분반기 검토 | D14: AA12000 | E14: 분석적절차 | F14: AA12002 | G14: 별도 | H14: 분반기 검토
B15: AA10000 | C15: 분반기 검토 | D15: AA12000 | E15: 분석적절차 | F15: AA12003 | G15: 연결 | H15: 분반기 검토
... B68: DD10000 | C68: IT 감사-RA | D68: DD10100 | E68: PM/Sub PM | F68: DD10110 | G68: 기타 | H68: N/A(RA-EL/PM 시간)
B69: DD10000 | C69: IT 감사-RA | D69: DD11000 | E69: Planning | F69: DD11001 | G69: 감사전략 검토 및 미팅 | H69: IT 감사-RA | I69: 내부통제-계획/종결
B70: DD10000 | C70: IT 감사-RA | D70: DD11000 | E70: Planning | F70: DD11002 | G70: Kick off template 작성 | H70: IT 감사-RA | I70: 내부통제-계획/종결
B71: DD10000 | C71: IT 감사-RA | D71: DD11000 | E71: Planning | F71: DD11005 | G71: Planning EGA 문서화 | H71: IT 감사-RA | I71: 내부통제-계획/종결
B72: DD10000 | C72: IT 감사-RA | D72: DD11000 | E72: Planning | F72: DD11009 | G72: 기타 | H72: IT 감사-RA | I72: 내부통제-계획/종결
B73: DD10000 | C73: IT 감사-RA | D73: DD12000 | E73: 설계평가 | F73: DD12001 | G73: ITGC | H73: IT 감사-RA | I73: 설계평가-내부통제-ITGC
B74: DD10000 | C74: IT 감사-RA | D74: DD13000 | E74: 운영평가 | F74: DD13001 | G74: ITGC | H74: IT 감사-RA | I74: 운영평가-내부통제-ITGC
B75: DD10000 | C75: IT 감사-RA | D75: DD14000 | E75: 설계 및 운영평가 | F75: DD14001 | G75: 자동통제_매출/매출채권 | H75: IT 감사-RA | I75: 설계평가-내부통제-매출/매출채권
B76: DD10000 | C76: IT 감사-RA | D76: DD14000 | E76: 설계 및 운영평가 | F76: DD14002 | G76: 자동통제_재고/원가 | H76: IT 감사-RA | I76: 설계평가-내부통제-재고/원가
B77: DD10000 | C77: IT 감사-RA | D77: DD14000 | E77: 설계 및 운영평가 | F77: DD14003 | G77: 자동통제_매입/매입채무 | H77: IT 감사-RA | I77: 설계평가-내부통제-매입/매입채무
B78: DD10000 | C78: IT 감사-RA | D78: DD14000 | E78: 설계 및 운영평가 | F78: DD14004 | G78: 자동통제_재무보고 | H78: IT 감사-RA | I78: 설계평가-내부통제-재무보고(FR)
B79: DD10000 | C79: IT 감사-RA | D79: DD14000 | E79: 설계 및 운영평가 | F79: DD14005 | G79: 자동통제_연결 | H79: IT 감사-RA | I79: 설계평가-내부통제-연결
B80: DD10000 | C80: IT 감사-RA | D80: DD14000 | E80: 설계 및 운영평가 | F80: DD14006 | G80: 자동통제_여신 | H80: IT 감사-RA | I80: (금융)설계평가-내부통제-대출채권
... B93: DD10000 | C93: IT 감사-RA | D93: DD19000 | E93: 기타 | F93: DD19001 | G93: - | H93: IT 감사-RA | I93: 내부통제-계획/종결
B94: EE10000 | C94: 재무제표 수준 위험 | D94: EE11000 | E94: 부정위험 | F94: EE11001 | G94: - | H94: 부정위험
B95: EE10000 | C95: 재무제표 수준 위험 | D95: EE12000 | E95: 계속기업 | F95: EE12001 | G95: - | H95: 계속기업
B96: EE10000 | C96: 재무제표 수준 위험 | D96: EE14000 | E96: 특수관계자 거래 | F96: EE14001 | G96: - | H96: 기타(특수관계자/법률 및 규정)
B97: EE10000 | C97: 재무제표 수준 위험 | D97: EE15000 | E97: 법률 및 규정 | F97: EE15001 | G97: - | H97: 기타(특수관계자/법률 및 규정)
B98: FF10000 | C98: 자산 | D98: FF10100 | E98: 현금 및 현금성자산 | F98: FF10102 | G98: 총괄표&증감분석 | H98: 현금및현금성자산-일반
B99: FF10000 | C99: 자산 | D99: FF10100 | E99: 현금 및 현금성자산 | F99: FF10103 | G99: 계정 이해 및 감사계획 수립 | H99: 현금및현금성자산-일반
B100: FF10000 | C100: 자산 | D100: FF10100 | E100: 현금 및 현금성자산 | F100: FF10108 | G100: 금융기관 조회절차 | H100: 현금및현금성자산-조회
B101: FF10000 | C101: 자산 | D101: FF10100 | E101: 현금 및 현금성자산 | F101: FF10109 | G101: 기업신용공여정보 대사절차 | H101: 현금및현금성자산-일반
B102: FF10000 | C102: 자산 | D102: FF10100 | E102: 현금 및 현금성자산 | F102: FF10110 | G102: 현금성자산 분류 | H102: 현금및현금성자산-일반
B103: FF10000 | C103: 자산 | D103: FF10100 | E103: 현금 및 현금성자산 | F103: FF10115 | G103: 이자수익 테스트-FS | H103: 현금및현금성자산-일반
B104: FF10000 | C104: 자산 | D104: FF10100 | E104: 현금 및 현금성자산 | F104: FF10120 | G104: 기타 | H104: 현금및현금성자산-일반
...

Sheet DB_rVal
A1: 이름 | B1: 참조 | C1: Indirect1 | D1: Indirect2 | E1: 상태 | F1: 비고1 | G1: 비고2
A2: Range_1_01 | B2: ='B_ET 기본정보'!$C$5 | C2: {=INDIRECT(A2)} -> ⑤ 도소매업 | D2: {=INDIRECT(SUBSTITUTE(B2,"=",""))} -> ⑤ 도소매업 | E2: =C2=D2 -> TRUE | F2: 1. 당기 감사 Client 기본 정보 << 지원코드인경우는 미작성 | G2: 1) 표준산업분류
A3: Range_1_02 | B3: ='B_ET 기본정보'!$C$6 | C3: {=INDIRECT(A3)} -> ⑤ 별도 1천억미만 ~ 500억이상 | D3: {=INDIRECT(SUBSTITUTE(B3,"=",""))} -> ⑤ 별도 1천억미만 ~ 500억이상 | E3: =C3=D3 -> TRUE | F3: 1. 당기 감사 Client 기본 정보 << 지원코드인경우는 미작성 | G3: 2) 자산규모
A4: Range_1_03 | B4: ='B_ET 기본정보'!$C$7 | C4: {=INDIRECT(A4)} -> ⑥ 비상장 | D4: {=INDIRECT(SUBSTITUTE(B4,"=",""))} -> ⑥ 비상장 | E4: =C4=D4 -> TRUE | F4: 1. 당기 감사 Client 기본 정보 << 지원코드인경우는 미작성 | G4: 3) 상장/비상장
A5: Range_1_04 | B5: ='B_ET 기본정보'!$C$8 | C5: {=INDIRECT(A5)} -> ② 사업보고서 제출미대상 | D5: {=INDIRECT(SUBSTITUTE(B5,"=",""))} -> ② 사업보고서 제출미대상 | E5: =C5=D5 -> TRUE | F5: 1. 당기 감사 Client 기본 정보 << 지원코드인경우는 미작성 | G5: 4) 사업보고서 제출
A6: Range_1_05 | B6: ='B_ET 기본정보'!$C$9 | C6: {=INDIRECT(A6)} -> ① IFRS | D6: {=INDIRECT(SUBSTITUTE(B6,"=",""))} -> ① IFRS | E6: =C6=D6 -> TRUE | F6: 1. 당기 감사 Client 기본 정보 << 지원코드인경우는 미작성 | G6: 5) GAAP
A7: Range_1_06 | B7: ='B_ET 기본정보'!$C$10 | C7: {=INDIRECT(A7)} -> ② 미작성 | D7: {=INDIRECT(SUBSTITUTE(B7,"=",""))} -> ② 미작성 | E7: =C7=D7 -> TRUE | F7: 1. 당기 감사 Client 기본 정보 << 지원코드인경우는 미작성 | G7: 6) 연결재무제표작성
A8: Range_1_07 | B8: ='B_ET 기본정보'!$C$11 | C8: {=INDIRECT(A8)} -> ① 없음 | D8: {=INDIRECT(SUBSTITUTE(B8,"=",""))} -> ① 없음 | E8: =C8=D8 -> TRUE | F8: 1. 당기 감사 Client 기본 정보 << 지원코드인경우는 미작성 | G8: 7) 연결자회사수
A9: Range_1_08 | B9: ='B_ET 기본정보'!$C$12 | C9: {=INDIRECT(A9)} -> ② 내부회계감사(별도) | D9: {=INDIRECT(SUBSTITUTE(B9,"=",""))} -> ② 내부회계감사(별도) | E9: =C9=D9 -> TRUE | F9: 1. 당기 감사 Client 기본 정보 << 지원코드인경우는 미작성 | G9: 8) 내부회계관리제도
A10: Range_1_09 | B10: ='B_ET 기본정보'!$C$13 | C10: {=INDIRECT(A10)} -> ① 초도감사 | D10: {=INDIRECT(SUBSTITUTE(B10,"=",""))} -> ① 초도감사 | E10: =C10=D10 -> TRUE | F10: 1. 당기 감사 Client 기본 정보 << 지원코드인경우는 미작성 | G10: 9) 초도감사
A11: Range_1_10 | B11: ='B_ET 기본정보'!$C$14 | C11: {=INDIRECT(A11)} -> 45748 | D11: {=INDIRECT(SUBSTITUTE(B11,"=",""))} -> 45748 | E11: =C11=D11 -> TRUE | F11: 1. 당기 감사 Client 기본 정보 << 지원코드인경우는 미작성 | G11: 10) 업무개시일
A12: Range_1_11 | B12: ='B_ET 기본정보'!$C$15 | C12: {=INDIRECT(A12)} -> 500 | D12: {=INDIRECT(SUBSTITUTE(B12,"=",""))} -> 500 | E12: =C12=D12 -> TRUE | F12: 1. 당기 감사 Client 기본 정보 << 지원코드인경우는 미작성 | G12: 11) 총계약시간
A13: Range_2_01 | B13: ='B_ET 기본정보'!$C$20 | C13: {=INDIRECT(A13)} -> 15916-01-012 | D13: {=INDIRECT(SUBSTITUTE(B13,"=",""))} -> 15916-01-012 | E13: =C13=D13 -> TRUE | F13: 2. 프로젝트 코드 기본정보 | G13: 1) Project code
... A51: Range_Header_12 | B51: ='D_2606 budget template'!$V$21 | C51: {=INDIRECT(A51)} -> 46082 | D51: {=INDIRECT(SUBSTITUTE(B51,"=",""))} -> 46082 | E51: =C51=D51 -> TRUE | F51: Header | G51: HeaderDatevalue12

Sheet DB_cList
B1: 비금융 | G1: 금융 | L1: 업무개시연월
B3: 분반기 검토 | D3: 분반기 검토 | E3: 분반기 검토 | G3: 분반기 검토 | I3: 분반기 검토 | J3: 분반기 검토 | K3: =_xlfn.XLOOKUP(J3,Tbl_Budget[Budget 관리단위],Tbl_Budget[Budget 관리단위]) -> 분반기 검토 | L3: 45658
B4: 계획단계 | D4: 계획단계 | E4: 계획단계 | G4: 계획단계 | I4: 계획단계 | J4: 계획단계 | K4: =_xlfn.XLOOKUP(J4,Tbl_Budget[Budget 관리단위],Tbl_Budget[Budget 관리단위]) -> 계획단계 | L4: =EDATE(L3,1) -> 45689
B5: 재무제표 수준 위험 | D5: 계획단계 | E5: 초도감사 | G5: 재무제표 수준 위험 | I5: 계획단계 | J5: 초도감사 | K5: =_xlfn.XLOOKUP(J5,Tbl_Budget[Budget 관리단위],Tbl_Budget[Budget 관리단위]) -> 초도감사 | L5: =EDATE(L4,1) -> 45717
B6: 자산 | D6: 재무제표 수준 위험 | E6: 부정위험 | G6: 자산 | I6: 재무제표 수준 위험 | J6: 부정위험 | K6: =_xlfn.XLOOKUP(J6,Tbl_Budget[Budget 관리단위],Tbl_Budget[Budget 관리단위]) -> 부정위험 | L6: =EDATE(L5,1) -> 45748
B7: 부채 및 자본 | D7: 재무제표 수준 위험 | E7: 계속기업 | G7: 부채 및 자본 | I7: 재무제표 수준 위험 | J7: 계속기업 | K7: =_xlfn.XLOOKUP(J7,Tbl_Budget[Budget 관리단위],Tbl_Budget[Budget 관리단위]) -> 계속기업 | L7: =EDATE(L6,1) -> 45778
B8: 수익/비용 | D8: 재무제표 수준 위험 | E8: 기타(특수관계자/법률 및 규정) | G8: 수익/비용 | I8: 재무제표 수준 위험 | J8: 기타(특수관계자/법률 및 규정) | K8: =_xlfn.XLOOKUP(J8,Tbl_Budget[Budget 관리단위],Tbl_Budget[Budget 관리단위]) -> 기타(특수관계자/법률 및 규정) | L8: =EDATE(L7,1) -> 45809
B9: 종결단계 | D9: 자산 | E9: 현금및현금성자산-일반 | G9: 종결단계 | I9: 자산 | J9: 현금및현금성자산-일반 | K9: =_xlfn.XLOOKUP(J9,Tbl_Budget[Budget 관리단위],Tbl_Budget[Budget 관리단위]) -> 현금및현금성자산-일반 | L9: =EDATE(L8,1) -> 45839
B10: 연결 | D10: 자산 | E10: 현금및현금성자산-조회 | G10: 연결 | I10: 자산 | J10: 현금및현금성자산-조회 | K10: =_xlfn.XLOOKUP(J10,Tbl_Budget[Budget 관리단위],Tbl_Budget[Budget 관리단위]) -> 현금및현금성자산-조회 | L10: =EDATE(L9,1) -> 45870
B11: 내부통제 | D11: 자산 | E11: 채무 및 지분증권-일반 | G11: 내부통제 | I11: 자산 | J11: 채무 및 지분증권-일반 | K11: =_xlfn.XLOOKUP(J11,Tbl_Budget[Budget 관리단위],Tbl_Budget[Budget 관리단위]) -> 채무 및 지분증권-일반 | L11: =EDATE(L10,1) -> 45901
B12: IT 감사-RA | D12: 자산 | E12: 채무 및 지분증권-공정가치평가 | G12: KICS | I12: 자산 | J12: 채무 및 지분증권-공정가치평가 | K12: =_xlfn.XLOOKUP(J12,Tbl_Budget[Budget 관리단위],Tbl_Budget[Budget 관리단위]) -> 채무 및 지분증권-공정가치평가 | L12: =EDATE(L11,1) -> 45931
D13: 자산 | E13: 파생상품 | G13: IT 감사-RA | I13: 자산 | J13: 파생상품 | K13: =_xlfn.XLOOKUP(J13,Tbl_Budget[Budget 관리단위],Tbl_Budget[Budget 관리단위]) -> 파생상품 | L13: =EDATE(L12,1) -> 45962
D14: 자산 | E14: 매출채권-일반 | I14: 자산 | J14: 매출채권-일반 | K14: =_xlfn.XLOOKUP(J14,Tbl_Budget[Budget 관리단위],Tbl_Budget[Budget 관리단위]) -> 매출채권-일반 | L14: =EDATE(L13,1) -> 45992
D15: 자산 | E15: 매출채권-조회 | I15: 자산 | J15: 매출채권-조회 | K15: =_xlfn.XLOOKUP(J15,Tbl_Budget[Budget 관리단위],Tbl_Budget[Budget 관리단위]) -> 매출채권-조회 | L15: =EDATE(L14,1) -> 46023
D16: 자산 | E16: 고객 반품, 할인 및 충당금 | I16: 자산 | J16: 대출채권-일반 | K16: =_xlfn.XLOOKUP(J16,Tbl_Budget[Budget 관리단위],Tbl_Budget[Budget 관리단위]) -> #N/A | L16: =EDATE(L15,1) -> 46054
D17: 자산 | E17: 재고자산-일반 | I17: 자산 | J17: 대출채권-조회 및 약정서 확인 | K17: =_xlfn.XLOOKUP(J17,Tbl_Budget[Budget 관리단위],Tbl_Budget[Budget 관리단위]) -> #N/A | L17: =EDATE(L16,1) -> 46082
D18: 자산 | E18: 재고자산-실사입회및문서화 | I18: 자산 | J18: 대출채권 대손충당금 - 일반 | K18: =_xlfn.XLOOKUP(J18,Tbl_Budget[Budget 관리단위],Tbl_Budget[Budget 관리단위]) -> #N/A | L18: =EDATE(L17,1) -> 46113
D19: 자산 | E19: 건설계약 | I19: 자산 | J19: 대출채권 대손충당금 - Risk Component 검증 | K19: =_xlfn.XLOOKUP(J19,Tbl_Budget[Budget 관리단위],Tbl_Budget[Budget 관리단위]) -> #N/A | L19: =EDATE(L18,1) -> 46143
D20: 자산 | E20: 기타자산 | I20: 자산 | J20: 대출채권 대손충당금 - Forward Looking 검증 | K20: =_xlfn.XLOOKUP(J20,Tbl_Budget[Budget 관리단위],Tbl_Budget[Budget 관리단위]) -> #N/A
D21: 자산 | E21: 유/무형자산/투자부동산-일반 | I21: 자산 | J21: 고객 반품, 할인 및 충당금 | K21: =_xlfn.XLOOKUP(J21,Tbl_Budget[Budget 관리단위],Tbl_Budget[Budget 관리단위]) -> 고객 반품, 할인 및 충당금
D22: 자산 | E22: 유/무형자산/투자부동산-취득처분 | I22: 자산 | J22: 재고자산-일반 | K22: =_xlfn.XLOOKUP(J22,Tbl_Budget[Budget 관리단위],Tbl_Budget[Budget 관리단위]) -> 재고자산-일반
D23: 자산 | E23: 종속기업 등에 대한 투자자산-일반 | I23: 자산 | J23: 재고자산-실사입회및문서화 | K23: =_xlfn.XLOOKUP(J23,Tbl_Budget[Budget 관리단위],Tbl_Budget[Budget 관리단위]) -> 재고자산-실사입회및문서화
D24: 자산 | E24: 종속기업 등에 대한 투자자산-손상검토 | I24: 자산 | J24: 건설계약 | K24: =_xlfn.XLOOKUP(J24,Tbl_Budget[Budget 관리단위],Tbl_Budget[Budget 관리단위]) -> 건설계약
D25: 자산 | E25: 영업권-일반 | I25: 자산 | J25: 기타자산 | K25: =_xlfn.XLOOKUP(J25,Tbl_Budget[Budget 관리단위],Tbl_Budget[Budget 관리단위]) -> 기타자산
D26: 자산 | E26: 영업권-PPA | I26: 자산 | J26: 유/무형자산/투자부동산-일반 | K26: =_xlfn.XLOOKUP(J26,Tbl_Budget[Budget 관리단위],Tbl_Budget[Budget 관리단위]) -> 유/무형자산/투자부동산-일반
D27: 자산 | E27: 영업권-손상검토 | I27: 자산 | J27: 유/무형자산/투자부동산-취득처분 | K27: =_xlfn.XLOOKUP(J27,Tbl_Budget[Budget 관리단위],Tbl_Budget[Budget 관리단위]) -> 유/무형자산/투자부동산-취득처분
D28: 자산 | E28: 자산 - 기타 | I28: 자산 | J28: 종속기업 등에 대한 투자자산-일반 | K28: =_xlfn.XLOOKUP(J28,Tbl_Budget[Budget 관리단위],Tbl_Budget[Budget 관리단위]) -> 종속기업 등에 대한 투자자산-일반
D29: 부채 및 자본 | E29: 매입채무-일반 | I29: 자산 | J29: 종속기업 등에 대한 투자자산-손상검토 | K29: =_xlfn.XLOOKUP(J29,Tbl_Budget[Budget 관리단위],Tbl_Budget[Budget 관리단위]) -> 종속기업 등에 대한 투자자산-손상검토
D30: 부채 및 자본 | E30: 매입채무-조회 | I30: 자산 | J30: 영업권-일반 | K30: =_xlfn.XLOOKUP(J30,Tbl_Budget[Budget 관리단위],Tbl_Budget[Budget 관리단위]) -> 영업권-일반
D31: 부채 및 자본 | E31: 특수관계자/내부거래 | I31: 자산 | J31: 영업권-PPA | K31: =_xlfn.XLOOKUP(J31,Tbl_Budget[Budget 관리단위],Tbl_Budget[Budget 관리단위]) -> 영업권-PPA
... D87: IT 감사-RA | E87: IT 감사-RA | I87: 내부통제 | J87: 설계평가-내부통제-연결 | K87: =_xlfn.XLOOKUP(J87,Tbl_Budget[Budget 관리단위],Tbl_Budget[Budget 관리단위]) -> 설계평가-내부통제-연결
I88: 내부통제 | J88: 설계평가-내부통제-기타프로세스 | K88: =_xlfn.XLOOKUP(J88,Tbl_Budget[Budget 관리단위],Tbl_Budget[Budget 관리단위]) -> 설계평가-내부통제-기타프로세스
I89: 내부통제 | J89: (금융)설계평가-내부통제-유가증권 | K89: =_xlfn.XLOOKUP(J89,Tbl_Budget[Budget 관리단위],Tbl_Budget[Budget 관리단위]) -> #N/A
I90: 내부통제 | J90: (금융)설계평가-내부통제-파생상품 | K90: =_xlfn.XLOOKUP(J90,Tbl_Budget[Budget 관리단위],Tbl_Budget[Budget 관리단위]) -> #N/A
I91: 내부통제 | J91: (금융)설계평가-내부통제-대출채권 | K91: =_xlfn.XLOOKUP(J91,Tbl_Budget[Budget 관리단위],Tbl_Budget[Budget 관리단위]) -> #N/A
I92: 내부통제 | J92: (금융)설계평가-내부통제-대출채권 대손충당금 | K92: =_xlfn.XLOOKUP(J92,Tbl_Budget[Budget 관리단위],Tbl_Budget[Budget 관리단위]) -> #N/A
I93: 내부통제 | J93: (금융)설계평가-내부통제-예수부채 | K93: =_xlfn.XLOOKUP(J93,Tbl_Budget[Budget 관리단위],Tbl_Budget[Budget 관리단위]) -> #N/A
I94: 내부통제 | J94: (금융)설계평가-내부통제-보험계약부채(IFRS17) | K94: =_xlfn.XLOOKUP(J94,Tbl_Budget[Budget 관리단위],Tbl_Budget[Budget 관리단위]) -> #N/A
I95: 내부통제 | J95: (금융)설계평가-내부통제-재보험계약자산(IFRS17) | K95: =_xlfn.XLOOKUP(J95,Tbl_Budget[Budget 관리단위],Tbl_Budget[Budget 관리단위]) -> #N/A
I96: 내부통제 | J96: (금융)설계평가-내부통제-보험료/보험금/사업비 등 | K96: =_xlfn.XLOOKUP(J96,Tbl_Budget[Budget 관리단위],Tbl_Budget[Budget 관리단위]) -> #N/A
...

Sheet DB_tStat
A1: No | B1: 분류1 | C1: 분류2 | D1: 분류3 | E1: 분류4 | F1: 분반기 검토 | G1: 계획단계 | H1: 부정위험 | I1: 계속기업 | J1: 초도감사 | K1: 현금및현금성자산-일반 | L1: 현금및현금성자산-조회 | M1: 채무 및 지분증권-일반 | N1: 채무 및 지분증권-공정가치평가 | O1: 파생상품 | P1: 매출채권-일반 | Q1: 매출채권-조회 | R1: 고객 반품, 할인 및 충당금 | S1: 재고자산-일반 | T1: 재고자산-실사입회및문서화 | U1: 건설계약 | V1: 기타자산 | W1: 유/무형자산/투자부동산-일반 | X1: 유/무형자산/투자부동산-취득처분 | Y1: 종속기업 등에 대한 투자자산-일반 | Z1: 종속기업 등에 대한 투자자산-손상검토 | AA1: 영업권-일반 | AB1: 영업권-PPA | AC1: 영업권-손상검토 | AD1: 자산 - 기타 | AE1: 매입채무-일반 | AF1: 매입채무-조회 | AG1: 특수관계자/내부거래 | AH1: 기타부채 및 충당부채-일반 | AI1: 기타부채 및 충당부채-부외부채/우발부채검토 | AJ1: 법인세 | AK1: 차입금/복합금융상품-일반 | AL1: 차입금/복합금융상품-약정사항 검토 | AM1: 이연수익 | AN1: 리스 | AO1: 퇴직급여/장기종업원급여 | AP1: 부채 - 기타 | AQ1: 자본금 및 기타 자본 계정 | AR1: 매출(IIFRS15/K-GAAP)-일반 | AS1: 매출(IIFRS15/K-GAAP)-발생사실테스트 | AT1: 매출(IIFRS15/K-GAAP)-Cut-off테스트 | AU1: 기타 영업수익 | AV1: 매출원가-일반 | AW1: 매출원가-증빙테스트 | AX1: 영업비용 | AY1: 인건비 | AZ1: 영업외손익 | BA1: 주식기준보상비용-일반 | BB1: 비용 - 기타 | BC1: 종결단계 | BD1: 주석검토-별도 | BE1: 주석검토-연결 | BF1: 기말감사 - 별도CF | BG1: 기말감사 - 연결일반 | BH1: 기말감사 - 연결GA/CA | BI1: 기말감사 - 연결법인세 | BJ1: 기말감사 - 연결CF | BK1: 설계평가-내부통제-기타프로세스 | BL1: 설계평가-내부통제-ELC | BM1: 설계평가-내부통제-재무보고(FR) | BN1: 설계평가-내부통제-자금 | BO1: 설계평가-내부통제-매출/매출채권 | BP1: 설계평가-내부통제-재고/원가 | BQ1: 설계평가-내부통제-매입/매입채무 | BR1: 설계평가-내부통제-급여/퇴직급여 | BS1: 설계평가-내부통제-유/무형자산/투자부동산 | BT1: 설계평가-내부통제-연결 | BU1: 설계평가-내부통제-ITGC | BV1: 내부통제-계획/종결 | BW1: 운영평가-내부통제-ELC | BX1: 운영평가-내부통제-재무보고(FR) | BY1: 운영평가-내부통제-자금 | BZ1: 운영평가-내부통제-매출/매출채권 | CA1: 운영평가-내부통제-재고/원가 | CB1: 운영평가-내부통제-매입/매입채무 | CC1: 운영평가-내부통제-급여/퇴직급여 | CD1: 운영평가-내부통제-유/무형자산/투자부동산 | CE1: 운영평가-내부통제-연결 | CF1: 운영평가-내부통제-ITGC | CG1: 운영평가-내부통제-기타프로세스 | CH1: 대출채권-일반 | CI1: 대출채권-조회 및 약정서 확인 | CJ1: 대출채권 대손충당금 - 일반 | CK1: 대출채권 대손충당금 - Risk Component 검증 | CL1: 대출채권 대손충당금 - Forward Looking 검증 | CM1: 재보험계약자산-일반 | CN1: 재보험계약자산-결산 | CO1: 예수부채 | CP1: 보험계약부채-일반 | CQ1: 보험계약부채-결산 | CR1: (금융)수수료 수익/비용 | CS1: (금융)설계평가-내부통제-유가증권 | CT1: (금융)설계평가-내부통제-파생상품 | CU1: (금융)설계평가-내부통제-대출채권 | CV1: (금융)설계평가-내부통제-대출채권 대손충당금 | CW1: (금융)설계평가-내부통제-예수부채 | CX1: (금융)설계평가-내부통제-보험계약부채(IFRS17) | CY1: (금융)설계평가-내부통제-재보험계약자산(IFRS17) | CZ1: (금융)설계평가-내부통제-보험료/보험금/사업비 등 | DA1: (금융)운영평가-내부통제-유가증권 | DB1: (금융)운영평가-내부통제-파생상품 | DC1: (금융)운영평가-내부통제-대출채권 | DD1: (금융)운영평가-내부통제-대출채권 대손충당금 | DE1: (금융)운영평가-내부통제-예수부채 | DF1: (금융)운영평가-내부통제-보험계약부채(IFRS17) | DG1: (금융)운영평가-내부통제-재보험계약자산(IFRS17) | DH1: (금융)운영평가-내부통제-보험료/보험금/사업비 등 | DI1: 최소영업자본액 검토 | DJ1: 순영업자본비율(NCR) 검토 | DK1: KICS - 일반 | DL1: KICS - 지급여력기준금액 | DM1: 차입금/복합금융상품-공정가치평가 | DN1: 외국어 보고서 | DO1: 내부회계검토 | DP1: 기타(특수관계자/법률 및 규정) | DQ1: 검증
